Workbook

Sheet Lisez-moi
A1: Setal Pro — Modèle financier sur 5 ans
A2: Version du 10/10/2026, construite par Claude (mode autonome). Toutes les valeurs en FCFA hors taxes (HT).
A4: Comment l'utiliser
A5: 1. Onglet Hypotheses : modifier uniquement les cellules en BLEU (sur fond jaune = hypothèses clés). Trois colonnes : Pessimiste / Central / Optimiste.
A6: 2. Choisir la version d'investissement (cellule D5 de Hypotheses) : 1 = frugale (≈ 46 M), 2 = standard (≈ 85 M).
A7: 3. Onglet Epargne : votre épargne mois par mois jusqu'à l'ouverture (apport, 500 € puis 1 000 €/mois, voyages).
A8: 4. Onglets Scen_Pessimiste / Scen_Central / Scen_Optimiste : compte de résultat, BFR et trésorerie mensuels sur 60 mois (octobre 2030 → septembre 2035), avec un bilan annuel en bas.
A9: 5. Onglet Synthese : comparaison des 3 scénarios, besoin de financement, couverture par l'épargne.
A11: Code couleur
A12: Bleu = saisie / hypothèse ; Noir = formule ; Vert = lien vers un autre onglet ; Fond jaune = hypothèse clé à vérifier en priorité.
A14: Simplifications assumées (à affiner)
A15: • TVA non modélisée (prix et coûts HT) : la TVA collectée/déductible est supposée neutre en trésorerie, hors décalages.
... A22: Sources : voir docs/04, 05, 06 et 07 du dossier. Les statuts [FAIT]/[HYPOTHÈSE]/[ESTIMATION]/À VÉRIFIER sont indiqués dans la colonne Statut des hypothèses.

Sheet Synthese
B1: Synthèse — 3 scénarios (FCFA HT)
B2: Toutes les valeurs sont des formules liées aux onglets de scénario. Version d'investissement : | F2: =IF(Hypotheses!$D$5=2,"standard","frugale") -> frugale
B4: Indicateur | C4: Pessimiste | D4: Central | E4: Optimiste
B5: Besoin de financement (creux de trésorerie, après crédit-bail) | C5: =Scen_Pessimiste!D71 -> 1.5052923e+08 | D5: =Scen_Central!D71 -> 49686495 | E5: =Scen_Optimiste!D71 -> 34254053
B6: Mois du creux | C6: =Scen_Pessimiste!D72 -> 49553 | D6: =Scen_Central!D72 -> 48122 | E6: =Scen_Optimiste!D72 -> 47818
B7: Coussin de sécurité | C7: =Scen_Pessimiste!D73 -> 8238000 | D7: =Scen_Central!D73 -> 7234218.8 | E7: =Scen_Optimiste!D73 -> 6894981.2
B8: Besoin total avec coussin | C8: =Scen_Pessimiste!D74 -> 1.5876723e+08 | D8: =Scen_Central!D74 -> 56920713 | E8: =Scen_Optimiste!D74 -> 41149035
B9: Épargne mobilisable | C9: =Scen_Pessimiste!D75 -> 24366258 | D9: =Scen_Central!D75 -> 24366258 | E9: =Scen_Optimiste!D75 -> 24366258
B10: Écart à financer (négatif = besoin non couvert) | C10: =Scen_Pessimiste!D76 -> -1.3440097e+08 | D10: =Scen_Central!D76 -> -32554455 | E10: =Scen_Optimiste!D76 -> -16782776
B11: Premier mois d'EBE positif | C11: =Scen_Pessimiste!D77 -> jamais | D11: =Scen_Central!D77 -> 48000 | E11: =Scen_Optimiste!D77 -> 47788
B12: Trésorerie minimale après apport | C12: =Scen_Pessimiste!D78 -> -1.2616297e+08 | D12: =Scen_Central!D78 -> -25320236 | E12: =Scen_Optimiste!D78 -> -9887794.8
B13: Montant financé en crédit-bail | C13: =Scen_Pessimiste!D79 -> 17088000 | D13: =Scen_Central!D79 -> 15130000 | E13: =Scen_Optimiste!D79 -> 15219000
B14: Loyer mensuel de crédit-bail | C14: =Scen_Pessimiste!D80 -> 466954.83 | D14: =Scen_Central!D80 -> 336558.49 | E14: =Scen_Optimiste!D80 -> 323358.77
B16: Année 1
B17: Volume moyen (kg/jour) | C17: =Scen_Pessimiste!E50 -> 83.043478 | D17: =Scen_Central!E50 -> 137.64706 | E17: =Scen_Optimiste!E50 -> 200
B18: Chiffre d'affaires | C18: =Scen_Pessimiste!E51 -> 14615367 | D18: =Scen_Central!E51 -> 31290593 | E18: =Scen_Optimiste!E51 -> 55206740
B19: EBE (EBITDA) | C19: =Scen_Pessimiste!E57 -> -27715193 | D19: =Scen_Central!E57 -> -7862450 | E19: =Scen_Optimiste!E57 -> 20036281
B20: Marge d'EBE | C20: =Scen_Pessimiste!E58 -> -1.8963049 | D20: =Scen_Central!E58 -> -0.251272 | E20: =Scen_Optimiste!E58 -> 0.36293178
B21: Résultat net | C21: =Scen_Pessimiste!E65 -> -38949666 | D21: =Scen_Central!E65 -> -17181968 | E21: =Scen_Optimiste!E65 -> 8296186.1
B22: Trésorerie de fin d'année (après apport) | C22: =Scen_Pessimiste!E67 -> -51212265 | D22: =Scen_Central!E67 -> -24645595 | E22: =Scen_Optimiste!E67 -> 4463577.5
B23: Point mort (kg/jour) | C23: =Scen_Pessimiste!E68 -> 347.41599 | D23: =Scen_Central!E68 -> 169.07127 | E23: =Scen_Optimiste!E68 -> 97.4638
B24: Année 2
B25: Volume moyen (kg/jour) | C25: =Scen_Pessimiste!F50 -> 176.95652 | D25: =Scen_Central!F50 -> 289.85294 | E25: =Scen_Optimiste!F50 -> 361.66667
B26: Chiffre d'affaires | C26: =Scen_Pessimiste!F51 -> 32483356 | D26: =Scen_Central!F51 -> 70171917 | E26: =Scen_Optimiste!F51 -> 1.0624319e+08
B27: EBE (EBITDA) | C27: =Scen_Pessimiste!F57 -> -16120864 | D27: =Scen_Central!F57 -> 19423053 | E27: =Scen_Optimiste!F57 -> 57606188
B28: Marge d'EBE | C28: =Scen_Pessimiste!F58 -> -0.49628073 | D28: =Scen_Central!F58 -> 0.2767924 | E28: =Scen_Optimiste!F58 -> 0.54221064
B29: Résultat net | C29: =Scen_Pessimiste!F65 -> -26843779 | D29: =Scen_Central!F65 -> 10401516 | E29: =Scen_Optimiste!F65 -> 34426138
B30: Trésorerie de fin d'année (après apport) | C30: =Scen_Pessimiste!F67 -> -76977618 | D30: =Scen_Central!F67 -> -14501572 | E30: =Scen_Optimiste!F67 -> 43633937
B31: Point mort (kg/jour) | C31: =Scen_Pessimiste!F68 -> 346.44549 | D31: =Scen_Central!F68 -> 173.43777 | E31: =Scen_Optimiste!F68 -> 117.09349
B32: Année 3
B33: Volume moyen (kg/jour) | C33: =Scen_Pessimiste!G50 -> 220 | D33: =Scen_Central!G50 -> 352.08333 | E33: =Scen_Optimiste!G50 -> 505
B34: Chiffre d'affaires | C34: =Scen_Pessimiste!G51 -> 42060255 | D34: =Scen_Central!G51 -> 90806660 | E34: =Scen_Optimiste!G51 -> 1.5785043e+08
B35: EBE (EBITDA) | C35: =Scen_Pessimiste!G57 -> -12616721 | D35: =Scen_Central!G57 -> 30485098 | E35: =Scen_Optimiste!G57 -> 93219323
B36: Marge d'EBE | C36: =Scen_Pessimiste!G58 -> -0.29996776 | D36: =Scen_Central!G58 -> 0.33571434 | E36: =Scen_Optimiste!G58 -> 0.59055478
B37: Résultat net | C37: =Scen_Pessimiste!G65 -> -22751680 | D37: =Scen_Central!G65 -> 17343668 | E37: =Scen_Optimiste!G65 -> 59065304
B38: Trésorerie de fin d'année (après apport) | C38: =Scen_Pessimiste!G67 -> -96551584 | D38: =Scen_Central!G67 -> 6796182.5 | E38: =Scen_Optimiste!G67 -> 1.1195413e+08
B39: Point mort (kg/jour) | C39: =Scen_Pessimiste!G68 -> 345.46699 | D39: =Scen_Central!G68 -> 182.54156 | E39: =Scen_Optimiste!G68 -> 135.45476
B40: Année 4
B41: Volume moyen (kg/jour) | C41: =Scen_Pessimiste!H50 -> 220 | D41: =Scen_Central!H50 -> 422.5 | E41: =Scen_Optimiste!H50 -> 616.66667
B42: Chiffre d'affaires | C42: =Scen_Pessimiste!H51 -> 43812766 | D42: =Scen_Central!H51 -> 1.1563196e+08 | E42: =Scen_Optimiste!H51 -> 2.0444254e+08
...

Sheet Hypotheses
B1: Hypothèses du modèle
B2: Saisir en bleu. Colonnes D/E/F = scénarios Pessimiste / Central / Optimiste.
B4: Paramètres globaux
B5: Version d'investissement (1 = frugale, 2 = standard) | D5: 1 | G5: Choix par défaut : frugale (épargne limitée). Voir docs/06 §9.
B6: Mois d'ouverture | D6: 47757 | G6: Objectif « fin 2030 » du porteur.
B7: Taux de change (FCFA pour 1 €) | D7: 655.957 | G7: [FAIT] Parité fixe euro / franc CFA (BCEAO).
B9: Paramètre | C9: Unité | D9: Pessimiste | E9: Central | F9: Optimiste | G9: Statut / source
B10: Volumes et capacité
B11: Volume au 1er mois | C11: kg/jour | D11: 40 | E11: 60 | F11: 80 | G11: [HYPOTHÈSE] premiers clients (docs/02 §4)
B12: Volume atteint en fin de montée en charge | C12: kg/jour | D12: 220 | E12: 300 | F12: 320 | G12: [HYPOTHÈSE] ≈ 15 à 25 clients (docs/02 §4)
B13: Durée de la montée en charge | C13: mois | D13: 24 | E13: 18 | F13: 12 | G13: [HYPOTHÈSE]
B14: Croissance après la montée en charge | C14: kg/jour par mois | D14: 0 | E14: 5 | F14: 10 | G14: [HYPOTHÈSE]
B15: Capacité en 1 équipe | C15: kg/jour | D15: 320 | E15: 320 | F15: 320 | G15: [ESTIMATION] goulot = lavage (docs/06 §3.2)
B16: Mois d'ouverture de la 2e équipe (99 = jamais) | C16: n° de mois | D16: 99 | E16: 30 | F16: 20 | G16: [HYPOTHÈSE] règle : charge > 85 % (docs/06 §3.2)
B17: Jours ouvrés par mois | C17: jours | D17: 26 | E17: 26 | F17: 26 | G17: [HYPOTHÈSE] 6 jours sur 7
B18: Prix et mix
B19: Prix Setal Entretien (linge du client) | C19: FCFA/kg | D19: 550 | E19: 700 | F19: 850 | G19: [HYPOTHÈSE] AUCUN prix B2B trouvé : priorité n°1 du terrain (docs/02 §6)
B20: Prix Setal Location (linge Setal Pro) | C20: FCFA/kg équivalent | D20: 950 | E20: 1100 | F20: 1250 | G20: [HYPOTHÈSE] entretien + amortissement du linge + marge (docs/04 §5.2)
B21: Part de location atteinte au mois 48 | C21: % des kg | D21: 0.25 | E21: 0.5 | F21: 0.6 | G21: [HYPOTHÈSE] stratégie de conversion (docs/02 §7)
B22: Consommables par kg de linge
B23: Eau | C23: L/kg | D23: 12 | E23: 10 | F23: 8 | G23: 9 à 12 L/kg (Electrolux, docs/06 S6)
B24: Prix de l'eau | C24: FCFA/m³ | D24: 880 | E24: 850 | F24: 800 | G24: Tranche haute SEN'EAU des ménages 779-878 ; tarif non domestique À VÉRIFIER
B25: Électricité | C25: kWh/kg | D25: 0.7 | E25: 0.6 | F25: 0.5 | G25: [HYPOTHÈSE] séchage et repassage au gaz
B26: Prix de l'électricité | C26: FCFA/kWh | D26: 210 | E26: 210 | F26: 190 | G26: [FAIT] PPP 3e tranche = 208,63 FCFA/kWh HT au 1/1/2026 (CRSE)
B27: Gaz (séchoirs, calandre) | C27: FCFA/kg | D27: 60 | E27: 50 | F27: 40 | G27: [HYPOTHÈSE] prix du gaz professionnel À VÉRIFIER
B28: Lessives et produits | C28: FCFA/kg | D28: 35 | E28: 30 | F28: 25 | G28: [HYPOTHÈSE]
B29: Emballages | C29: FCFA/kg | D29: 12 | E29: 10 | F29: 8 | G29: [HYPOTHÈSE]
B30: Surcoût groupe électrogène | C30: FCFA/kg | D30: 8 | E30: 3 | F30: 2 | G30: [HYPOTHÈSE] coupures (docs/06 §4)
B31: Linge en location
B32: Coût d'achat du linge | C32: FCFA/kg de linge | D32: 10000 | E32: 9000 | F32: 8000 | G32: [HYPOTHÈSE] prix du textile hôtelier À VÉRIFIER (terrain)
B33: Dotation (jeux en circulation) | C33: jours d'usage | D33: 4 | E33: 3.5 | F33: 3 | G33: [HYPOTHÈSE] 3 à 4 jeux par lit (docs/04 §3.2)
B34: Durée de vie du linge | C34: lavages | D34: 120 | E34: 150 | F34: 200 | G34: [HYPOTHÈSE] À VÉRIFIER (fiches fournisseurs)
B35: Pertes de linge | C35: % du stock par mois | D35: 0.02 | E35: 0.01 | F35: 0.005 | G35: [HYPOTHÈSE]
B36: Personnel (salaires bruts mensuels)
B37: Chef d'atelier | C37: FCFA/mois | D37: 200000 | E37: 200000 | F37: 200000 | G37: [HYPOTHÈSE] (docs/06 §10)
B38: Opérateur (moyenne) | C38: FCFA/mois | D38: 110000 | E38: 105000 | F38: 100000 | G38: [HYPOTHÈSE] salaire minimum ≈ 75 000 FCFA À VÉRIFIER
B39: Chauffeur-livreur | C39: FCFA/mois | D39: 130000 | E39: 130000 | F39: 130000 | G39: [HYPOTHÈSE]
B40: Charges sociales + CFCE | C40: % du brut | D40: 0.25 | E40: 0.22 | F40: 0.21 | G40: [ESTIMATION] taux CLEISS 2026 + CFCE 3 % (docs/05 §6)
B41: Opérateurs en démarrage | C41: personnes | D41: 2 | E41: 2 | F41: 2 | G41: Hors chef d'atelier et chauffeur
B42: Opérateurs en croisière | C42: personnes | D42: 4 | E42: 4 | F42: 4 | G42: (docs/06 §10)
...

Sheet Investissements
B1: Investissements de départ (FCFA)
B2: Montants en bleu = estimations (docs/06 §9), à remplacer par des devis. Durée = durée d'amortissement en années (0 = non amortissable).
B4: Poste | C4: Standard | D4: Frugale | E4: Retenu | F4: Durée (ans) | G4: Dotation mensuelle | H4: Crédit-bail (1 = oui)
B5: 3 laveuses-essoreuses (25 + 20 + 12 kg) | C5: 15000000 | D5: 7000000 | E5: =IF(Hypotheses!$D$5=2,C5,D5) -> 7000000 | F5: 8 | G5: =IF(F5>0,E5/F5/12,0) -> 72916.667 | H5: 1
B6: Séchoirs au gaz (2 × 25 kg ; frugal : 1) | C6: 9600000 | D6: 4800000 | E6: =IF(Hypotheses!$D$5=2,C6,D6) -> 4800000 | F6: 8 | G6: =IF(F6>0,E6/F6/12,0) -> 50000 | H6: 1
B7: Calandre-sécheuse de 2,5 m | C7: 11000000 | D7: 6000000 | E7: =IF(Hypotheses!$D$5=2,C7,D7) -> 6000000 | F7: 8 | G7: =IF(F7>0,E7/F7/12,0) -> 62500 | H7: 1
B8: Transport, dédouanement, installation | C8: 9000000 | D8: 4500000 | E8: =IF(Hypotheses!$D$5=2,C8,D8) -> 4500000 | F8: 8 | G8: =IF(F8>0,E8/F8/12,0) -> 46875 | H8: 0
B9: Groupe électrogène et inverseur | C9: 8000000 | D9: 5000000 | E9: =IF(Hypotheses!$D$5=2,C9,D9) -> 5000000 | F9: 7 | G9: =IF(F9>0,E9/F9/12,0) -> 59523.81 | H9: 0
B10: Cuve d'eau, surpresseur, adoucisseur | C10: 2500000 | D10: 1500000 | E10: =IF(Hypotheses!$D$5=2,C10,D10) -> 1500000 | F10: 7 | G10: =IF(F10>0,E10/F10/12,0) -> 17857.143 | H10: 0
B11: Prétraitement des eaux | C11: 2000000 | D11: 1500000 | E11: =IF(Hypotheses!$D$5=2,C11,D11) -> 1500000 | F11: 7 | G11: =IF(F11>0,E11/F11/12,0) -> 17857.143 | H11: 0
B12: Aménagement du local | C12: 8000000 | D12: 5000000 | E12: =IF(Hypotheses!$D$5=2,C12,D12) -> 5000000 | F12: 6 | G12: =IF(F12>0,E12/F12/12,0) -> 69444.444 | H12: 0
B13: Chariots, tables, rayonnages, balance | C13: 2500000 | D13: 1500000 | E13: =IF(Hypotheses!$D$5=2,C13,D13) -> 1500000 | F13: 5 | G13: =IF(F13>0,E13/F13/12,0) -> 25000 | H13: 0
B14: Véhicule utilitaire (occasion) | C14: 12000000 | D14: 6000000 | E14: =IF(Hypotheses!$D$5=2,C14,D14) -> 6000000 | F14: 5 | G14: =IF(F14>0,E14/F14/12,0) -> 100000 | H14: 0
B15: Informatique, téléphones, étiqueteuse, logiciel | C15: 1500000 | D15: 800000 | E15: =IF(Hypotheses!$D$5=2,C15,D15) -> 800000 | F15: 3 | G15: =IF(F15>0,E15/F15/12,0) -> 22222.222 | H15: 0
B16: Dépôt de garantie du local (3 mois) | C16: 1350000 | D16: 1050000 | E16: =IF(Hypotheses!$D$5=2,C16,D16) -> 1050000 | F16: 0 | G16: =IF(F16>0,E16/F16/12,0) -> 0 | H16: 0
B17: Création, études, environnement, conseil | C17: 2500000 | D17: 1800000 | E17: =IF(Hypotheses!$D$5=2,C17,D17) -> 1800000 | F17: 3 | G17: =IF(F17>0,E17/F17/12,0) -> 50000 | H17: 0
B18: Total | C18: =SUM(C5:C17) -> 84950000 | D18: =SUM(D5:D17) -> 46450000 | E18: =SUM(E5:E17) -> 46450000 | G18: =SUM(G5:G17) -> 594196.43
B19: Dont éligible au crédit-bail (machines, version retenue) | E19: =SUMPRODUCT(E5:E17,H5:H17) -> 17800000
B20: Total en euros (version retenue) | E20: =E18/Hypotheses!$D$7 -> 70812.569
B21: Choix du porteur (10/10/2026) : crédit-bail UNIQUEMENT sur les machines (laveuses, séchoirs, calandre). Mettre 1 en colonne H pour inclure un autre poste.

Sheet Epargne
B1: Épargne personnelle jusqu'à l'ouverture
B3: Apport actuel (octobre 2026) | C3: FCFA | D3: 10000000 | E3: Donnée du porteur (≈ 10 M FCFA)
B4: Épargne mensuelle actuelle | C4: €/mois | D4: 500 | E4: Donnée du porteur
B5: Épargne mensuelle visée | C5: €/mois | D5: 1000 | E5: Objectif du porteur
B6: Mois de passage à l'épargne visée | C6: date | D6: 46753 | E6: [HYPOTHÈSE] à confirmer
B7: Voyage 1 (exploration, ≈ 3 semaines) : coût | C7: FCFA | D7: 2000000 | E7: [ESTIMATION] vols, hébergement, transport sur place
B8: Voyage 1 : date | C8: date | D8: 46508 | E8: docs/03 §5
B9: Voyage 2 (confirmation, ≈ 2 semaines) : coût | C9: FCFA | D9: 1500000 | E9: [ESTIMATION]
B10: Voyage 2 : date | C10: date | D10: 46784 | E10: docs/03 §5
B11: Voyage 3 (création, local, devis, 2030) : coût | C11: FCFA | D11: 2000000 | E11: [ESTIMATION]
B12: Voyage 3 : date | C12: date | D12: 47543 | E12: docs/09
B13: Déménagement et installation au Sénégal | C13: FCFA | D13: 2500000 | E13: [ESTIMATION] payé le mois précédant l'ouverture
B14: Réserve personnelle de subsistance conservée hors projet | C14: mois | D14: 12 | E14: [HYPOTHÈSE] aucun salaire pendant ~4 ans : à confirmer
... B16: Rendement annuel de l'épargne | C16: % | D16: 0 | E16: [HYPOTHÈSE] prudence (0 %)
B18: Mois | C18: Épargne (€) | D18: Épargne (FCFA) | E18: Voyages et installation | F18: Intérêts | G18: Solde fin de mois | H18: Mois n°
B19: 46296 | C19: =IF(B19>=$D$6,$D$5,$D$4) -> 500 | D19: =C19*Hypotheses!$D$7 -> 327978.5 | E19: =-(IF(B19=$D$8,$D$7,0)+IF(B19=$D$10,$D$9,0)+IF(B19=$D$12,$D$11,0)+IF(B19=DATE(YEAR(Hypotheses!$D$6),MONTH(Hypotheses!$D$6)-1,1),$D$13,0)) -> 0 | F19: =$D$3*$D$16/12 -> 0 | G19: =$D$3+D19+E19+F19 -> 10327978 | H19: 1
B20: =DATE(YEAR(B19),MONTH(B19)+1,1) -> 46327 | C20: =IF(B20>=$D$6,$D$5,$D$4) -> 500 | D20: =C20*Hypotheses!$D$7 -> 327978.5 | E20: =-(IF(B20=$D$8,$D$7,0)+IF(B20=$D$10,$D$9,0)+IF(B20=$D$12,$D$11,0)+IF(B20=DATE(YEAR(Hypotheses!$D$6),MONTH(Hypotheses!$D$6)-1,1),$D$13,0)) -> 0 | F20: =G19*$D$16/12 -> 0 | G20: =G19+D20+E20+F20 -> 10655957 | H20: 2
B21: =DATE(YEAR(B20),MONTH(B20)+1,1) -> 46357 | C21: =IF(B21>=$D$6,$D$5,$D$4) -> 500 | D21: =C21*Hypotheses!$D$7 -> 327978.5 | E21: =-(IF(B21=$D$8,$D$7,0)+IF(B21=$D$10,$D$9,0)+IF(B21=$D$12,$D$11,0)+IF(B21=DATE(YEAR(Hypotheses!$D$6),MONTH(Hypotheses!$D$6)-1,1),$D$13,0)) -> 0 | F21: =G20*$D$16/12 -> 0 | G21: =G20+D21+E21+F21 -> 10983936 | H21: 3
B22: =DATE(YEAR(B21),MONTH(B21)+1,1) -> 46388 | C22: =IF(B22>=$D$6,$D$5,$D$4) -> 500 | D22: =C22*Hypotheses!$D$7 -> 327978.5 | E22: =-(IF(B22=$D$8,$D$7,0)+IF(B22=$D$10,$D$9,0)+IF(B22=$D$12,$D$11,0)+IF(B22=DATE(YEAR(Hypotheses!$D$6),MONTH(Hypotheses!$D$6)-1,1),$D$13,0)) -> 0 | F22: =G21*$D$16/12 -> 0 | G22: =G21+D22+E22+F22 -> 11311914 | H22: 4
B23: =DATE(YEAR(B22),MONTH(B22)+1,1) -> 46419 | C23: =IF(B23>=$D$6,$D$5,$D$4) -> 500 | D23: =C23*Hypotheses!$D$7 -> 327978.5 | E23: =-(IF(B23=$D$8,$D$7,0)+IF(B23=$D$10,$D$9,0)+IF(B23=$D$12,$D$11,0)+IF(B23=DATE(YEAR(Hypotheses!$D$6),MONTH(Hypotheses!$D$6)-1,1),$D$13,0)) -> 0 | F23: =G22*$D$16/12 -> 0 | G23: =G22+D23+E23+F23 -> 11639892 | H23: 5
B24: =DATE(YEAR(B23),MONTH(B23)+1,1) -> 46447 | C24: =IF(B24>=$D$6,$D$5,$D$4) -> 500 | D24: =C24*Hypotheses!$D$7 -> 327978.5 | E24: =-(IF(B24=$D$8,$D$7,0)+IF(B24=$D$10,$D$9,0)+IF(B24=$D$12,$D$11,0)+IF(B24=DATE(YEAR(Hypotheses!$D$6),MONTH(Hypotheses!$D$6)-1,1),$D$13,0)) -> 0 | F24: =G23*$D$16/12 -> 0 | G24: =G23+D24+E24+F24 -> 11967871 | H24: 6
B25: =DATE(YEAR(B24),MONTH(B24)+1,1) -> 46478 | C25: =IF(B25>=$D$6,$D$5,$D$4) -> 500 | D25: =C25*Hypotheses!$D$7 -> 327978.5 | E25: =-(IF(B25=$D$8,$D$7,0)+IF(B25=$D$10,$D$9,0)+IF(B25=$D$12,$D$11,0)+IF(B25=DATE(YEAR(Hypotheses!$D$6),MONTH(Hypotheses!$D$6)-1,1),$D$13,0)) -> 0 | F25: =G24*$D$16/12 -> 0 | G25: =G24+D25+E25+F25 -> 12295850 | H25: 7
B26: =DATE(YEAR(B25),MONTH(B25)+1,1) -> 46508 | C26: =IF(B26>=$D$6,$D$5,$D$4) -> 500 | D26: =C26*Hypotheses!$D$7 -> 327978.5 | E26: =-(IF(B26=$D$8,$D$7,0)+IF(B26=$D$10,$D$9,0)+IF(B26=$D$12,$D$11,0)+IF(B26=DATE(YEAR(Hypotheses!$D$6),MONTH(Hypotheses!$D$6)-1,1),$D$13,0)) -> -2000000 | F26: =G25*$D$16/12 -> 0 | G26: =G25+D26+E26+F26 -> 10623828 | H26: 8
B27: =DATE(YEAR(B26),MONTH(B26)+1,1) -> 46539 | C27: =IF(B27>=$D$6,$D$5,$D$4) -> 500 | D27: =C27*Hypotheses!$D$7 -> 327978.5 | E27: =-(IF(B27=$D$8,$D$7,0)+IF(B27=$D$10,$D$9,0)+IF(B27=$D$12,$D$11,0)+IF(B27=DATE(YEAR(Hypotheses!$D$6),MONTH(Hypotheses!$D$6)-1,1),$D$13,0)) -> 0 | F27: =G26*$D$16/12 -> 0 | G27: =G26+D27+E27+F27 -> 10951806 | H27: 9
B28: =DATE(YEAR(B27),MONTH(B27)+1,1) -> 46569 | C28: =IF(B28>=$D$6,$D$5,$D$4) -> 500 | D28: =C28*Hypotheses!$D$7 -> 327978.5 | E28: =-(IF(B28=$D$8,$D$7,0)+IF(B28=$D$10,$D$9,0)+IF(B28=$D$12,$D$11,0)+IF(B28=DATE(YEAR(Hypotheses!$D$6),MONTH(Hypotheses!$D$6)-1,1),$D$13,0)) -> 0 | F28: =G27*$D$16/12 -> 0 | G28: =G27+D28+E28+F28 -> 11279785 | H28: 10
B29: =DATE(YEAR(B28),MONTH(B28)+1,1) -> 46600 | C29: =IF(B29>=$D$6,$D$5,$D$4) -> 500 | D29: =C29*Hypotheses!$D$7 -> 327978.5 | E29: =-(IF(B29=$D$8,$D$7,0)+IF(B29=$D$10,$D$9,0)+IF(B29=$D$12,$D$11,0)+IF(B29=DATE(YEAR(Hypotheses!$D$6),MONTH(Hypotheses!$D$6)-1,1),$D$13,0)) -> 0 | F29: =G28*$D$16/12 -> 0 | G29: =G28+D29+E29+F29 -> 11607764 | H29: 11
B30: =DATE(YEAR(B29),MONTH(B29)+1,1) -> 46631 | C30: =IF(B30>=$D$6,$D$5,$D$4) -> 500 | D30: =C30*Hypotheses!$D$7 -> 327978.5 | E30: =-(IF(B30=$D$8,$D$7,0)+IF(B30=$D$10,$D$9,0)+IF(B30=$D$12,$D$11,0)+IF(B30=DATE(YEAR(Hypotheses!$D$6),MONTH(Hypotheses!$D$6)-1,1),$D$13,0)) -> 0 | F30: =G29*$D$16/12 -> 0 | G30: =G29+D30+E30+F30 -> 11935742 | H30: 12
B31: =DATE(YEAR(B30),MONTH(B30)+1,1) -> 46661 | C31: =IF(B31>=$D$6,$D$5,$D$4) -> 500 | D31: =C31*Hypotheses!$D$7 -> 327978.5 | E31: =-(IF(B31=$D$8,$D$7,0)+IF(B31=$D$10,$D$9,0)+IF(B31=$D$12,$D$11,0)+IF(B31=DATE(YEAR(Hypotheses!$D$6),MONTH(Hypotheses!$D$6)-1,1),$D$13,0)) -> 0 | F31: =G30*$D$16/12 -> 0 | G31: =G30+D31+E31+F31 -> 12263720 | H31: 13
... B126: =DATE(YEAR(B125),MONTH(B125)+1,1) -> 49553 | C126: =IF(B126>=$D$6,$D$5,$D$4) -> 1000 | D126: =C126*Hypotheses!$D$7 -> 655957 | E126: =-(IF(B126=$D$8,$D$7,0)+IF(B126=$D$10,$D$9,0)+IF(B126=$D$12,$D$11,0)+IF(B126=DATE(YEAR(Hypotheses!$D$6),MONTH(Hypotheses!$D$6)-1,1),$D$13,0)) -> 0 | F126: =G125*$D$16/12 -> 0 | G126: =G125+D126+E126+F126 -> 67923678 | H126: 108
B128: Solde d'épargne la veille de l'ouverture | G128: =INDEX(G19:G126,MATCH(DATE(YEAR(Hypotheses!$D$6),MONTH(Hypotheses!$D$6)-1,1),B19:B126,0)) -> 28566258
B129: Moins : réserve personnelle de subsistance | G129: =-$D$14*$D$15 -> -4200000
B130: Épargne mobilisable pour Setal Pro | G130: =G128+G129 -> 24366258
B131: Soit en euros | G131: =G130/Hypotheses!$D$7 -> 37146.122

Sheet Scen_Pessimiste
B1: Scénario Pessimiste — compte de résultat et trésorerie mensuels (FCFA HT)
B3: Mois n° | D3: =0 -> 0 | E3: =D3+1 -> 1 | F3: =E3+1 -> 2 | G3: =F3+1 -> 3 | H3: =G3+1 -> 4 | I3: =H3+1 -> 5 | J3: =I3+1 -> 6 | K3: =J3+1 -> 7 | L3: =K3+1 -> 8 | ... BL3: =BK3+1 -> 60
B4: Mois | D4: =DATE(YEAR(Hypotheses!$D$6),MONTH(Hypotheses!$D$6)-1,1) -> 47727 | E4: =DATE(YEAR(D4),MONTH(D4)+1,1) -> 47757 | F4: =DATE(YEAR(E4),MONTH(E4)+1,1) -> 47788 | G4: =DATE(YEAR(F4),MONTH(F4)+1,1) -> 47818 | H4: =DATE(YEAR(G4),MONTH(G4)+1,1) -> 47849 | I4: =DATE(YEAR(H4),MONTH(H4)+1,1) -> 47880 | J4: =DATE(YEAR(I4),MONTH(I4)+1,1) -> 47908 | K4: =DATE(YEAR(J4),MONTH(J4)+1,1) -> 47939 | L4: =DATE(YEAR(K4),MONTH(K4)+1,1) -> 47969 | ... BL4: =DATE(YEAR(BK4),MONTH(BK4)+1,1) -> 49553
B5: Année d'exploitation | E5: =INT((E3-1)/12)+1 -> 1 | F5: =INT((F3-1)/12)+1 -> 1 | G5: =INT((G3-1)/12)+1 -> 1 | H5: =INT((H3-1)/12)+1 -> 1 | I5: =INT((I3-1)/12)+1 -> 1 | J5: =INT((J3-1)/12)+1 -> 1 | K5: =INT((K3-1)/12)+1 -> 1 | L5: =INT((L3-1)/12)+1 -> 1 | ... BL5: =INT((BL3-1)/12)+1 -> 5
B6: Mois dans l'année | E6: =MOD(E3-1,12)+1 -> 1 | F6: =MOD(F3-1,12)+1 -> 2 | G6: =MOD(G3-1,12)+1 -> 3 | H6: =MOD(H3-1,12)+1 -> 4 | I6: =MOD(I3-1,12)+1 -> 5 | J6: =MOD(J3-1,12)+1 -> 6 | K6: =MOD(K3-1,12)+1 -> 7 | L6: =MOD(L3-1,12)+1 -> 8 | ... BL6: =MOD(BL3-1,12)+1 -> 12
B7: Activité
B8: Capacité | C8: kg/jour | E8: =Hypotheses!$D$15*IF(E3>=Hypotheses!$D$16,2,1) -> 320 | F8: =Hypotheses!$D$15*IF(F3>=Hypotheses!$D$16,2,1) -> 320 | G8: =Hypotheses!$D$15*IF(G3>=Hypotheses!$D$16,2,1) -> 320 | H8: =Hypotheses!$D$15*IF(H3>=Hypotheses!$D$16,2,1) -> 320 | I8: =Hypotheses!$D$15*IF(I3>=Hypotheses!$D$16,2,1) -> 320 | J8: =Hypotheses!$D$15*IF(J3>=Hypotheses!$D$16,2,1) -> 320 | K8: =Hypotheses!$D$15*IF(K3>=Hypotheses!$D$16,2,1) -> 320 | L8: =Hypotheses!$D$15*IF(L3>=Hypotheses!$D$16,2,1) -> 320 | ... BL8: =Hypotheses!$D$15*IF(BL3>=Hypotheses!$D$16,2,1) -> 320
B9: Volume traité | C9: kg/jour | E9: =MIN(E8,Hypotheses!$D$11+(Hypotheses!$D$12-Hypotheses!$D$11)*MIN(1,(E3-1)/MAX(1,Hypotheses!$D$13-1))+Hypotheses!$D$14*MAX(0,E3-Hypotheses!$D$13)) -> 40 | F9: =MIN(F8,Hypotheses!$D$11+(Hypotheses!$D$12-Hypotheses!$D$11)*MIN(1,(F3-1)/MAX(1,Hypotheses!$D$13-1))+Hypotheses!$D$14*MAX(0,F3-Hypotheses!$D$13)) -> 47.826087 | G9: =MIN(G8,Hypotheses!$D$11+(Hypotheses!$D$12-Hypotheses!$D$11)*MIN(1,(G3-1)/MAX(1,Hypotheses!$D$13-1))+Hypotheses!$D$14*MAX(0,G3-Hypotheses!$D$13)) -> 55.652174 | H9: =MIN(H8,Hypotheses!$D$11+(Hypotheses!$D$12-Hypotheses!$D$11)*MIN(1,(H3-1)/MAX(1,Hypotheses!$D$13-1))+Hypotheses!$D$14*MAX(0,H3-Hypotheses!$D$13)) -> 63.478261 | I9: =MIN(I8,Hypotheses!$D$11+(Hypotheses!$D$12-Hypotheses!$D$11)*MIN(1,(I3-1)/MAX(1,Hypotheses!$D$13-1))+Hypotheses!$D$14*MAX(0,I3-Hypotheses!$D$13)) -> 71.304348 | J9: =MIN(J8,Hypotheses!$D$11+(Hypotheses!$D$12-Hypotheses!$D$11)*MIN(1,(J3-1)/MAX(1,Hypotheses!$D$13-1))+Hypotheses!$D$14*MAX(0,J3-Hypotheses!$D$13)) -> 79.130435 | K9: =MIN(K8,Hypotheses!$D$11+(Hypotheses!$D$12-Hypotheses!$D$11)*MIN(1,(K3-1)/MAX(1,Hypotheses!$D$13-1))+Hypotheses!$D$14*MAX(0,K3-Hypotheses!$D$13)) -> 86.956522 | L9: =MIN(L8,Hypotheses!$D$11+(Hypotheses!$D$12-Hypotheses!$D$11)*MIN(1,(L3-1)/MAX(1,Hypotheses!$D$13-1))+Hypotheses!$D$14*MAX(0,L3-Hypotheses!$D$13)) -> 94.782609 | ... BL9: =MIN(BL8,Hypotheses!$D$11+(Hypotheses!$D$12-Hypotheses!$D$11)*MIN(1,(BL3-1)/MAX(1,Hypotheses!$D$13-1))+Hypotheses!$D$14*MAX(0,BL3-Hypotheses!$D$13)) -> 220
B10: Taux de charge | C10: % | E10: =IF(E8>0,E9/E8,0) -> 0.125 | F10: =IF(F8>0,F9/F8,0) -> 0.14945652 | G10: =IF(G8>0,G9/G8,0) -> 0.17391304 | H10: =IF(H8>0,H9/H8,0) -> 0.19836957 | I10: =IF(I8>0,I9/I8,0) -> 0.22282609 | J10: =IF(J8>0,J9/J8,0) -> 0.24728261 | K10: =IF(K8>0,K9/K8,0) -> 0.27173913 | L10: =IF(L8>0,L9/L8,0) -> 0.29619565 | ... BL10: =IF(BL8>0,BL9/BL8,0) -> 0.6875
B11: Volume mensuel | C11: kg/mois | E11: =E9*Hypotheses!$D$17 -> 1040 | F11: =F9*Hypotheses!$D$17 -> 1243.4783 | G11: =G9*Hypotheses!$D$17 -> 1446.9565 | H11: =H9*Hypotheses!$D$17 -> 1650.4348 | I11: =I9*Hypotheses!$D$17 -> 1853.913 | J11: =J9*Hypotheses!$D$17 -> 2057.3913 | K11: =K9*Hypotheses!$D$17 -> 2260.8696 | L11: =L9*Hypotheses!$D$17 -> 2464.3478 | ... BL11: =BL9*Hypotheses!$D$17 -> 5720
B12: Part de location | C12: % | E12: =Hypotheses!$D$21*MIN(1,(E3-1)/47) -> 0 | F12: =Hypotheses!$D$21*MIN(1,(F3-1)/47) -> 0.0053191489 | G12: =Hypotheses!$D$21*MIN(1,(G3-1)/47) -> 0.010638298 | H12: =Hypotheses!$D$21*MIN(1,(H3-1)/47) -> 0.015957447 | I12: =Hypotheses!$D$21*MIN(1,(I3-1)/47) -> 0.021276596 | J12: =Hypotheses!$D$21*MIN(1,(J3-1)/47) -> 0.026595745 | K12: =Hypotheses!$D$21*MIN(1,(K3-1)/47) -> 0.031914894 | L12: =Hypotheses!$D$21*MIN(1,(L3-1)/47) -> 0.037234043 | ... BL12: =Hypotheses!$D$21*MIN(1,(BL3-1)/47) -> 0.25
B13: dont Setal Entretien | C13: kg/mois | E13: =E11*(1-E12) -> 1040 | F13: =F11*(1-F12) -> 1236.864 | G13: =G11*(1-G12) -> 1431.5634 | H13: =H11*(1-H12) -> 1624.0981 | I13: =I11*(1-I12) -> 1814.4681 | J13: =J11*(1-J12) -> 2002.6735 | K13: =K11*(1-K12) -> 2188.7142 | L13: =L11*(1-L12) -> 2372.5902 | ... BL13: =BL11*(1-BL12) -> 4290
B14: dont Setal Location | C14: kg/mois | E14: =E11*E12 -> 0 | F14: =F11*F12 -> 6.6142461 | G14: =G11*G12 -> 15.393154 | H14: =H11*H12 -> 26.336725 | I14: =I11*I12 -> 39.444958 | J14: =J11*J12 -> 54.717854 | K14: =K11*K12 -> 72.155412 | L14: =L11*L12 -> 91.757632 | ... BL14: =BL11*BL12 -> 1430
B15: Compte de résultat
B16: CA Setal Entretien | C16: FCFA | E16: =E13*Hypotheses!$D$19 -> 572000 | F16: =F13*Hypotheses!$D$19 -> 680275.21 | G16: =G13*Hypotheses!$D$19 -> 787359.85 | H16: =H13*Hypotheses!$D$19 -> 893253.93 | I16: =I13*Hypotheses!$D$19 -> 997957.45 | J16: =J13*Hypotheses!$D$19 -> 1101470.4 | K16: =K13*Hypotheses!$D$19 -> 1203792.8 | L16: =L13*Hypotheses!$D$19 -> 1304924.6 | ... BL16: =BL13*Hypotheses!$D$19 -> 2359500
B17: CA Setal Location | C17: FCFA | E17: =E14*Hypotheses!$D$20 -> 0 | F17: =F14*Hypotheses!$D$20 -> 6283.5338 | G17: =G14*Hypotheses!$D$20 -> 14623.497 | H17: =H14*Hypotheses!$D$20 -> 25019.889 | I17: =I14*Hypotheses!$D$20 -> 37472.71 | J17: =J14*Hypotheses!$D$20 -> 51981.961 | K17: =K14*Hypotheses!$D$20 -> 68547.641 | L17: =L14*Hypotheses!$D$20 -> 87169.75 | ... BL17: =BL14*Hypotheses!$D$20 -> 1358500
B18: Chiffre d'affaires | C18: FCFA | E18: =E16+E17 -> 572000 | F18: =F16+F17 -> 686558.74 | G18: =G16+G17 -> 801983.35 | H18: =H16+H17 -> 918273.82 | I18: =I16+I17 -> 1035430.2 | J18: =J16+J17 -> 1153452.4 | K18: =K16+K17 -> 1272340.4 | L18: =L16+L17 -> 1392094.4 | ... BL18: =BL16+BL17 -> 3718000
B19: Consommables (eau, énergie, gaz, produits, emballages) | C19: FCFA | E19: =-E11*(Hypotheses!$D$23*Hypotheses!$D$24/1000+Hypotheses!$D$25*Hypotheses!$D$26+Hypotheses!$D$27+Hypotheses!$D$28+Hypotheses!$D$29+Hypotheses!$D$30) -> -283462.4 | F19: =-F11*(Hypotheses!$D$23*Hypotheses!$D$24/1000+Hypotheses!$D$25*Hypotheses!$D$26+Hypotheses!$D$27+Hypotheses!$D$28+Hypotheses!$D$29+Hypotheses!$D$30) -> -338922.43 | G19: =-G11*(Hypotheses!$D$23*Hypotheses!$D$24/1000+Hypotheses!$D$25*Hypotheses!$D$26+Hypotheses!$D$27+Hypotheses!$D$28+Hypotheses!$D$29+Hypotheses!$D$30) -> -394382.47 | H19: =-H11*(Hypotheses!$D$23*Hypotheses!$D$24/1000+Hypotheses!$D$25*Hypotheses!$D$26+Hypotheses!$D$27+Hypotheses!$D$28+Hypotheses!$D$29+Hypotheses!$D$30) -> -449842.5 | I19: =-I11*(Hypotheses!$D$23*Hypotheses!$D$24/1000+Hypotheses!$D$25*Hypotheses!$D$26+Hypotheses!$D$27+Hypotheses!$D$28+Hypotheses!$D$29+Hypotheses!$D$30) -> -505302.54 | J19: =-J11*(Hypotheses!$D$23*Hypotheses!$D$24/1000+Hypotheses!$D$25*Hypotheses!$D$26+Hypotheses!$D$27+Hypotheses!$D$28+Hypotheses!$D$29+Hypotheses!$D$30) -> -560762.57 | K19: =-K11*(Hypotheses!$D$23*Hypotheses!$D$24/1000+Hypotheses!$D$25*Hypotheses!$D$26+Hypotheses!$D$27+Hypotheses!$D$28+Hypotheses!$D$29+Hypotheses!$D$30) -> -616222.61 | L19: =-L11*(Hypotheses!$D$23*Hypotheses!$D$24/1000+Hypotheses!$D$25*Hypotheses!$D$26+Hypotheses!$D$27+Hypotheses!$D$28+Hypotheses!$D$29+Hypotheses!$D$30) -> -671682.64 | ... BL19: =-BL11*(Hypotheses!$D$23*Hypotheses!$D$24/1000+Hypotheses!$D$25*Hypotheses!$D$26+Hypotheses!$D$27+Hypotheses!$D$28+Hypotheses!$D$29+Hypotheses!$D$30) -> -1559043.2
B20: Stock de linge en location nécessaire | C20: FCFA | D20: =0 -> 0 | E20: =E14/Hypotheses!$D$17*Hypotheses!$D$33*Hypotheses!$D$32 -> 0 | F20: =F14/Hypotheses!$D$17*Hypotheses!$D$33*Hypotheses!$D$32 -> 10175.763 | G20: =G14/Hypotheses!$D$17*Hypotheses!$D$33*Hypotheses!$D$32 -> 23681.776 | H20: =H14/Hypotheses!$D$17*Hypotheses!$D$33*Hypotheses!$D$32 -> 40518.039 | I20: =I14/Hypotheses!$D$17*Hypotheses!$D$33*Hypotheses!$D$32 -> 60684.551 | J20: =J14/Hypotheses!$D$17*Hypotheses!$D$33*Hypotheses!$D$32 -> 84181.314 | K20: =K14/Hypotheses!$D$17*Hypotheses!$D$33*Hypotheses!$D$32 -> 111008.33 | L20: =L14/Hypotheses!$D$17*Hypotheses!$D$33*Hypotheses!$D$32 -> 141165.59 | ... BL20: =BL14/Hypotheses!$D$17*Hypotheses!$D$33*Hypotheses!$D$32 -> 2200000
B21: Usure et pertes du linge en location | C21: FCFA | E21: =-(E14/Hypotheses!$D$34*Hypotheses!$D$32+E20*Hypotheses!$D$35) -> 0 | F21: =-(F14/Hypotheses!$D$34*Hypotheses!$D$32+F20*Hypotheses!$D$35) -> -754.70244 | G21: =-(G14/Hypotheses!$D$34*Hypotheses!$D$32+G20*Hypotheses!$D$35) -> -1756.3984 | H21: =-(H14/Hypotheses!$D$34*Hypotheses!$D$32+H20*Hypotheses!$D$35) -> -3005.0879 | I21: =-(I14/Hypotheses!$D$34*Hypotheses!$D$32+I20*Hypotheses!$D$35) -> -4500.7709 | J21: =-(J14/Hypotheses!$D$34*Hypotheses!$D$32+J20*Hypotheses!$D$35) -> -6243.4474 | K21: =-(K14/Hypotheses!$D$34*Hypotheses!$D$32+K20*Hypotheses!$D$35) -> -8233.1175 | L21: =-(L14/Hypotheses!$D$34*Hypotheses!$D$32+L20*Hypotheses!$D$35) -> -10469.781 | ... BL21: =-(BL14/Hypotheses!$D$34*Hypotheses!$D$32+BL20*Hypotheses!$D$35) -> -163166.67
B22: Marge sur coûts variables | C22: FCFA | E22: =E18+E19+E21 -> 288537.6 | F22: =F18+F19+F21 -> 346881.6 | G22: =G18+G19+G21 -> 405844.48 | H22: =H18+H19+H21 -> 465426.23 | I22: =I18+I19+I21 -> 525626.85 | J22: =J18+J19+J21 -> 586446.34 | K22: =K18+K19+K21 -> 647884.7 | L22: =L18+L19+L21 -> 709941.93 | ... BL22: =BL18+BL19+BL21 -> 1995790.1
B23: Opérateurs | C23: personnes | E23: =IF(E9>=Hypotheses!$D$43,Hypotheses!$D$42,Hypotheses!$D$41)+IF(E3>=Hypotheses!$D$16,Hypotheses!$D$46,0) -> 2 | F23: =IF(F9>=Hypotheses!$D$43,Hypotheses!$D$42,Hypotheses!$D$41)+IF(F3>=Hypotheses!$D$16,Hypotheses!$D$46,0) -> 2 | G23: =IF(G9>=Hypotheses!$D$43,Hypotheses!$D$42,Hypotheses!$D$41)+IF(G3>=Hypotheses!$D$16,Hypotheses!$D$46,0) -> 2 | H23: =IF(H9>=Hypotheses!$D$43,Hypotheses!$D$42,Hypotheses!$D$41)+IF(H3>=Hypotheses!$D$16,Hypotheses!$D$46,0) -> 2 | I23: =IF(I9>=Hypotheses!$D$43,Hypotheses!$D$42,Hypotheses!$D$41)+IF(I3>=Hypotheses!$D$16,Hypotheses!$D$46,0) -> 2 | J23: =IF(J9>=Hypotheses!$D$43,Hypotheses!$D$42,Hypotheses!$D$41)+IF(J3>=Hypotheses!$D$16,Hypotheses!$D$46,0) -> 2 | K23: =IF(K9>=Hypotheses!$D$43,Hypotheses!$D$42,Hypotheses!$D$41)+IF(K3>=Hypotheses!$D$16,Hypotheses!$D$46,0) -> 2 | L23: =IF(L9>=Hypotheses!$D$43,Hypotheses!$D$42,Hypotheses!$D$41)+IF(L3>=Hypotheses!$D$16,Hypotheses!$D$46,0) -> 2 | ... BL23: =IF(BL9>=Hypotheses!$D$43,Hypotheses!$D$42,Hypotheses!$D$41)+IF(BL3>=Hypotheses!$D$16,Hypotheses!$D$46,0) -> 4
B24: 2e véhicule en service (1 = oui) | D24: =0 -> 0 | E24: =IF(OR(E9>=Hypotheses!$D$44,D24=1),1,0) -> 0 | F24: =IF(OR(F9>=Hypotheses!$D$44,E24=1),1,0) -> 0 | G24: =IF(OR(G9>=Hypotheses!$D$44,F24=1),1,0) -> 0 | H24: =IF(OR(H9>=Hypotheses!$D$44,G24=1),1,0) -> 0 | I24: =IF(OR(I9>=Hypotheses!$D$44,H24=1),1,0) -> 0 | J24: =IF(OR(J9>=Hypotheses!$D$44,I24=1),1,0) -> 0 | K24: =IF(OR(K9>=Hypotheses!$D$44,J24=1),1,0) -> 0 | L24: =IF(OR(L9>=Hypotheses!$D$44,K24=1),1,0) -> 0 | ... BL24: =IF(OR(BL9>=Hypotheses!$D$44,BK24=1),1,0) -> 0
B25: Salaires et charges sociales | C25: FCFA | E25: =-(Hypotheses!$D$37+Hypotheses!$D$39*(1+E24)+E23*Hypotheses!$D$38)*(1+Hypotheses!$D$40)*Hypotheses!$D$47/12 -> -744791.67 | F25: =-(Hypotheses!$D$37+Hypotheses!$D$39*(1+F24)+F23*Hypotheses!$D$38)*(1+Hypotheses!$D$40)*Hypotheses!$D$47/12 -> -744791.67 | G25: =-(Hypotheses!$D$37+Hypotheses!$D$39*(1+G24)+G23*Hypotheses!$D$38)*(1+Hypotheses!$D$40)*Hypotheses!$D$47/12 -> -744791.67 | H25: =-(Hypotheses!$D$37+Hypotheses!$D$39*(1+H24)+H23*Hypotheses!$D$38)*(1+Hypotheses!$D$40)*Hypotheses!$D$47/12 -> -744791.67 | I25: =-(Hypotheses!$D$37+Hypotheses!$D$39*(1+I24)+I23*Hypotheses!$D$38)*(1+Hypotheses!$D$40)*Hypotheses!$D$47/12 -> -744791.67 | J25: =-(Hypotheses!$D$37+Hypotheses!$D$39*(1+J24)+J23*Hypotheses!$D$38)*(1+Hypotheses!$D$40)*Hypotheses!$D$47/12 -> -744791.67 | K25: =-(Hypotheses!$D$37+Hypotheses!$D$39*(1+K24)+K23*Hypotheses!$D$38)*(1+Hypotheses!$D$40)*Hypotheses!$D$47/12 -> -744791.67 | L25: =-(Hypotheses!$D$37+Hypotheses!$D$39*(1+L24)+L23*Hypotheses!$D$38)*(1+Hypotheses!$D$40)*Hypotheses!$D$47/12 -> -744791.67 | ... BL25: =-(Hypotheses!$D$37+Hypotheses!$D$39*(1+BL24)+BL23*Hypotheses!$D$38)*(1+Hypotheses!$D$40)*Hypotheses!$D$47/12 -> -1042708.3
B26: Loyer | C26: FCFA | E26: =-Hypotheses!$D$49*Hypotheses!$D$50 -> -600000 | F26: =-Hypotheses!$D$49*Hypotheses!$D$50 -> -600000 | G26: =-Hypotheses!$D$49*Hypotheses!$D$50 -> -600000 | H26: =-Hypotheses!$D$49*Hypotheses!$D$50 -> -600000 | I26: =-Hypotheses!$D$49*Hypotheses!$D$50 -> -600000 | J26: =-Hypotheses!$D$49*Hypotheses!$D$50 -> -600000 | K26: =-Hypotheses!$D$49*Hypotheses!$D$50 -> -600000 | L26: =-Hypotheses!$D$49*Hypotheses!$D$50 -> -600000 | ... BL26: =-Hypotheses!$D$49*Hypotheses!$D$50 -> -600000
B27: Autres charges fixes (véhicule, assurances, maintenance, comptable, télécom, marketing, divers, abonnements) | C27: FCFA | E27: =-(Hypotheses!$D$51*(1+E24)+Investissements!$E$18*(1+Hypotheses!$D$60)*(Hypotheses!$D$52+Hypotheses!$D$53)/12+Hypotheses!$D$54+Hypotheses!$D$55+Hypotheses!$D$56+Hypotheses!$D$57+Hypotheses!$D$58) -> -1252250 | F27: =-(Hypotheses!$D$51*(1+F24)+Investissements!$E$18*(1+Hypotheses!$D$60)*(Hypotheses!$D$52+Hypotheses!$D$53)/12+Hypotheses!$D$54+Hypotheses!$D$55+Hypotheses!$D$56+Hypotheses!$D$57+Hypotheses!$D$58) -> -1252250 | G27: =-(Hypotheses!$D$51*(1+G24)+Investissements!$E$18*(1+Hypotheses!$D$60)*(Hypotheses!$D$52+Hypotheses!$D$53)/12+Hypotheses!$D$54+Hypotheses!$D$55+Hypotheses!$D$56+Hypotheses!$D$57+Hypotheses!$D$58) -> -1252250 | H27: =-(Hypotheses!$D$51*(1+H24)+Investissements!$E$18*(1+Hypotheses!$D$60)*(Hypotheses!$D$52+Hypotheses!$D$53)/12+Hypotheses!$D$54+Hypotheses!$D$55+Hypotheses!$D$56+Hypotheses!$D$57+Hypotheses!$D$58) -> -1252250 | I27: =-(Hypotheses!$D$51*(1+I24)+Investissements!$E$18*(1+Hypotheses!$D$60)*(Hypotheses!$D$52+Hypotheses!$D$53)/12+Hypotheses!$D$54+Hypotheses!$D$55+Hypotheses!$D$56+Hypotheses!$D$57+Hypotheses!$D$58) -> -1252250 | J27: =-(Hypotheses!$D$51*(1+J24)+Investissements!$E$18*(1+Hypotheses!$D$60)*(Hypotheses!$D$52+Hypotheses!$D$53)/12+Hypotheses!$D$54+Hypotheses!$D$55+Hypotheses!$D$56+Hypotheses!$D$57+Hypotheses!$D$58) -> -1252250 | K27: =-(Hypotheses!$D$51*(1+K24)+Investissements!$E$18*(1+Hypotheses!$D$60)*(Hypotheses!$D$52+Hypotheses!$D$53)/12+Hypotheses!$D$54+Hypotheses!$D$55+Hypotheses!$D$56+Hypotheses!$D$57+Hypotheses!$D$58) -> -1252250 | L27: =-(Hypotheses!$D$51*(1+L24)+Investissements!$E$18*(1+Hypotheses!$D$60)*(Hypotheses!$D$52+Hypotheses!$D$53)/12+Hypotheses!$D$54+Hypotheses!$D$55+Hypotheses!$D$56+Hypotheses!$D$57+Hypotheses!$D$58) -> -1252250 | ... BL27: =-(Hypotheses!$D$51*(1+BL24)+Investissements!$E$18*(1+Hypotheses!$D$60)*(Hypotheses!$D$52+Hypotheses!$D$53)/12+Hypotheses!$D$54+Hypotheses!$D$55+Hypotheses!$D$56+Hypotheses!$D$57+Hypotheses!$D$58) -> -1252250
B28: Frais avant ouverture | C28: FCFA | D28: =-Hypotheses!$D$61 -> -4000000 | E28: =0 -> 0 | F28: =0 -> 0 | G28: =0 -> 0 | H28: =0 -> 0 | I28: =0 -> 0 | J28: =0 -> 0 | K28: =0 -> 0 | L28: =0 -> 0 | ... BL28: =0 -> 0
B29: EBE (EBITDA) | C29: FCFA | D29: =D28 -> -4000000 | E29: =E22+E25+E26+E27+E28 -> -2308504.1 | F29: =F22+F25+F26+F27+F28 -> -2250160.1 | G29: =G22+G25+G26+G27+G28 -> -2191197.2 | H29: =H22+H25+H26+H27+H28 -> -2131615.4 | I29: =I22+I25+I26+I27+I28 -> -2071414.8 | J29: =J22+J25+J26+J27+J28 -> -2010595.3 | K29: =K22+K25+K26+K27+K28 -> -1949157 | L29: =L22+L25+L26+L27+L28 -> -1887099.7 | ... BL29: =BL22+BL25+BL26+BL27+BL28 -> -899168.2
B30: Dotations aux amortissements (équipements) | C30: FCFA | E30: =-SUMPRODUCT((Investissements!$F$5:$F$17*12>=E3)*Investissements!$G$5:$G$17)*(1+Hypotheses!$D$60)-E24*Hypotheses!$D$45/60 -> -713035.71 | F30: =-SUMPRODUCT((Investissements!$F$5:$F$17*12>=F3)*Investissements!$G$5:$G$17)*(1+Hypotheses!$D$60)-F24*Hypotheses!$D$45/60 -> -713035.71 | G30: =-SUMPRODUCT((Investissements!$F$5:$F$17*12>=G3)*Investissements!$G$5:$G$17)*(1+Hypotheses!$D$60)-G24*Hypotheses!$D$45/60 -> -713035.71 | H30: =-SUMPRODUCT((Investissements!$F$5:$F$17*12>=H3)*Investissements!$G$5:$G$17)*(1+Hypotheses!$D$60)-H24*Hypotheses!$D$45/60 -> -713035.71 | I30: =-SUMPRODUCT((Investissements!$F$5:$F$17*12>=I3)*Investissements!$G$5:$G$17)*(1+Hypotheses!$D$60)-I24*Hypotheses!$D$45/60 -> -713035.71 | J30: =-SUMPRODUCT((Investissements!$F$5:$F$17*12>=J3)*Investissements!$G$5:$G$17)*(1+Hypotheses!$D$60)-J24*Hypotheses!$D$45/60 -> -713035.71 | K30: =-SUMPRODUCT((Investissements!$F$5:$F$17*12>=K3)*Investissements!$G$5:$G$17)*(1+Hypotheses!$D$60)-K24*Hypotheses!$D$45/60 -> -713035.71 | L30: =-SUMPRODUCT((Investissements!$F$5:$F$17*12>=L3)*Investissements!$G$5:$G$17)*(1+Hypotheses!$D$60)-L24*Hypotheses!$D$45/60 -> -713035.71 | ... BL30: =-SUMPRODUCT((Investissements!$F$5:$F$17*12>=BL3)*Investissements!$G$5:$G$17)*(1+Hypotheses!$D$60)-BL24*Hypotheses!$D$45/60 -> -626369.05
B31: Résultat d'exploitation (EBIT) | C31: FCFA | D31: =D29 -> -4000000 | E31: =E29+E30 -> -3021539.8 | F31: =F29+F30 -> -2963195.8 | G31: =G29+G30 -> -2904232.9 | H31: =H29+H30 -> -2844651.2 | I31: =I29+I30 -> -2784450.5 | J31: =J29+J30 -> -2723631 | K31: =K29+K30 -> -2662192.7 | L31: =L29+L30 -> -2600135.4 | ... BL31: =BL29+BL30 -> -1525537.2
B32: Trésorerie
B33: Créances clients (fin de mois) | C33: FCFA | D33: =0 -> 0 | E33: =E18*Hypotheses!$D$62/30 -> 1144000 | F33: =F18*Hypotheses!$D$62/30 -> 1373117.5 | G33: =G18*Hypotheses!$D$62/30 -> 1603966.7 | H33: =H18*Hypotheses!$D$62/30 -> 1836547.6 | I33: =I18*Hypotheses!$D$62/30 -> 2070860.3 | J33: =J18*Hypotheses!$D$62/30 -> 2306904.7 | K33: =K18*Hypotheses!$D$62/30 -> 2544680.9 | L33: =L18*Hypotheses!$D$62/30 -> 2784188.7 | ... BL33: =BL18*Hypotheses!$D$62/30 -> 7436000
B34: Dettes fournisseurs (fin de mois) | C34: FCFA | D34: =0 -> 0 | E34: =-E19*Hypotheses!$D$63/30 -> 141731.2 | F34: =-F19*Hypotheses!$D$63/30 -> 169461.22 | G34: =-G19*Hypotheses!$D$63/30 -> 197191.23 | H34: =-H19*Hypotheses!$D$63/30 -> 224921.25 | I34: =-I19*Hypotheses!$D$63/30 -> 252651.27 | J34: =-J19*Hypotheses!$D$63/30 -> 280381.29 | K34: =-K19*Hypotheses!$D$63/30 -> 308111.3 | L34: =-L19*Hypotheses!$D$63/30 -> 335841.32 | ... BL34: =-BL19*Hypotheses!$D$63/30 -> 779521.6
B35: BFR | C35: FCFA | D35: =D33-D34 -> 0 | E35: =E33-E34 -> 1002268.8 | F35: =F33-F34 -> 1203656.3 | G35: =G33-G34 -> 1406775.5 | H35: =H33-H34 -> 1611626.4 | I35: =I33-I34 -> 1818209 | J35: =J33-J34 -> 2026523.4 | K35: =K33-K34 -> 2236569.5 | ... BL35: =BL33-BL34 -> 6656478.4
B36: Variation du BFR | C36: FCFA | E36: =-(E35-D35) -> -1002268.8 | F36: =-(F35-E35) -> -201387.47 | G36: =-(G35-F35) -> -203119.2 | H36: =-(H35-G35) -> -204850.93 | I36: =-(I35-H35) -> -206582.66 | J36: =-(J35-I35) -> -208314.39 | K36: =-(K35-J35) -> -210046.12 | L36: =-(L35-K35) -> -211777.85 | ... BL36: =-(BL35-BK35) -> 0
B37: Investissements en équipements (hors part financée en crédit-bail) | C37: FCFA | D37: =-Investissements!$E$18*(1+Hypotheses!$D$60)+(Investissements!$E$19*(1+Hypotheses!$D$60)*Hypotheses!$D$69*(1-Hypotheses!$D$70)) -> -38652000 | E37: =-MAX(0,E24-D24)*Hypotheses!$D$45 -> 0 | F37: =-MAX(0,F24-E24)*Hypotheses!$D$45 -> 0 | G37: =-MAX(0,G24-F24)*Hypotheses!$D$45 -> 0 | H37: =-MAX(0,H24-G24)*Hypotheses!$D$45 -> 0 | I37: =-MAX(0,I24-H24)*Hypotheses!$D$45 -> 0 | J37: =-MAX(0,J24-I24)*Hypotheses!$D$45 -> 0 | K37: =-MAX(0,K24-J24)*Hypotheses!$D$45 -> 0 | L37: =-MAX(0,L24-K24)*Hypotheses!$D$45 -> 0 | ... BL37: =-MAX(0,BL24-BK24)*Hypotheses!$D$45 -> 0
B38: Achats de linge (constitution du stock) | C38: FCFA | E38: =-MAX(0,E20-D20) -> 0 | F38: =-MAX(0,F20-E20) -> -10175.763 | G38: =-MAX(0,G20-F20) -> -13506.013 | H38: =-MAX(0,H20-G20) -> -16836.263 | I38: =-MAX(0,I20-H20) -> -20166.512 | J38: =-MAX(0,J20-I20) -> -23496.762 | K38: =-MAX(0,K20-J20) -> -26827.012 | L38: =-MAX(0,L20-K20) -> -30157.262 | ... BL38: =-MAX(0,BL20-BK20) -> 0
B39: Impôt payé | C39: FCFA | E39: =IF(AND(E6=1,E5>1),-INDEX($E$64:$I$64,E5-1),0) -> 0 | F39: =IF(AND(F6=1,F5>1),-INDEX($E$64:$I$64,F5-1),0) -> 0 | G39: =IF(AND(G6=1,G5>1),-INDEX($E$64:$I$64,G5-1),0) -> 0 | H39: =IF(AND(H6=1,H5>1),-INDEX($E$64:$I$64,H5-1),0) -> 0 | I39: =IF(AND(I6=1,I5>1),-INDEX($E$64:$I$64,I5-1),0) -> 0 | J39: =IF(AND(J6=1,J5>1),-INDEX($E$64:$I$64,J5-1),0) -> 0 | K39: =IF(AND(K6=1,K5>1),-INDEX($E$64:$I$64,K5-1),0) -> 0 | L39: =IF(AND(L6=1,L5>1),-INDEX($E$64:$I$64,L5-1),0) -> 0 | ... BL39: =IF(AND(BL6=1,BL5>1),-INDEX($E$64:$I$64,BL5-1),0) -> 0
B40: Loyers de crédit-bail payés | C40: FCFA | E40: =IF(E3<=Hypotheses!$D$72,PMT(Hypotheses!$D$71/12,Hypotheses!$D$72,(Investissements!$E$19*(1+Hypotheses!$D$60)*Hypotheses!$D$69*(1-Hypotheses!$D$70))),0) -> -466954.83 | F40: =IF(F3<=Hypotheses!$D$72,PMT(Hypotheses!$D$71/12,Hypotheses!$D$72,(Investissements!$E$19*(1+Hypotheses!$D$60)*Hypotheses!$D$69*(1-Hypotheses!$D$70))),0) -> -466954.83 | G40: =IF(G3<=Hypotheses!$D$72,PMT(Hypotheses!$D$71/12,Hypotheses!$D$72,(Investissements!$E$19*(1+Hypotheses!$D$60)*Hypotheses!$D$69*(1-Hypotheses!$D$70))),0) -> -466954.83 | H40: =IF(H3<=Hypotheses!$D$72,PMT(Hypotheses!$D$71/12,Hypotheses!$D$72,(Investissements!$E$19*(1+Hypotheses!$D$60)*Hypotheses!$D$69*(1-Hypotheses!$D$70))),0) -> -466954.83 | I40: =IF(I3<=Hypotheses!$D$72,PMT(Hypotheses!$D$71/12,Hypotheses!$D$72,(Investissements!$E$19*(1+Hypotheses!$D$60)*Hypotheses!$D$69*(1-Hypotheses!$D$70))),0) -> -466954.83 | J40: =IF(J3<=Hypotheses!$D$72,PMT(Hypotheses!$D$71/12,Hypotheses!$D$72,(Investissements!$E$19*(1+Hypotheses!$D$60)*Hypotheses!$D$69*(1-Hypotheses!$D$70))),0) -> -466954.83 | K40: =IF(K3<=Hypotheses!$D$72,PMT(Hypotheses!$D$71/12,Hypotheses!$D$72,(Investissements!$E$19*(1+Hypotheses!$D$60)*Hypotheses!$D$69*(1-Hypotheses!$D$70))),0) -> -466954.83 | L40: =IF(L3<=Hypotheses!$D$72,PMT(Hypotheses!$D$71/12,Hypotheses!$D$72,(Investissements!$E$19*(1+Hypotheses!$D$60)*Hypotheses!$D$69*(1-Hypotheses!$D$70))),0) -> -466954.83 | ... BL40: =IF(BL3<=Hypotheses!$D$72,PMT(Hypotheses!$D$71/12,Hypotheses!$D$72,(Investissements!$E$19*(1+Hypotheses!$D$60)*Hypotheses!$D$69*(1-Hypotheses!$D$70))),0) -> 0
B41: Capital restant dû en crédit-bail (fin de mois) | C41: FCFA | D41: =(Investissements!$E$19*(1+Hypotheses!$D$60)*Hypotheses!$D$69*(1-Hypotheses!$D$70)) -> 17088000 | E41: =IF(E3<=Hypotheses!$D$72,D41*(1+Hypotheses!$D$71/12)+E40,0) -> 16820405 | F41: =IF(F3<=Hypotheses!$D$72,E41*(1+Hypotheses!$D$71/12)+F40,0) -> 16549688 | G41: =IF(G3<=Hypotheses!$D$72,F41*(1+Hypotheses!$D$71/12)+G40,0) -> 16275813 | H41: =IF(H3<=Hypotheses!$D$72,G41*(1+Hypotheses!$D$71/12)+H40,0) -> 15998743 | I41: =IF(I3<=Hypotheses!$D$72,H41*(1+Hypotheses!$D$71/12)+I40,0) -> 15718440 | J41: =IF(J3<=Hypotheses!$D$72,I41*(1+Hypotheses!$D$71/12)+J40,0) -> 15434867 | K41: =IF(K3<=Hypotheses!$D$72,J41*(1+Hypotheses!$D$71/12)+K40,0) -> 15147986 | L41: =IF(L3<=Hypotheses!$D$72,K41*(1+Hypotheses!$D$71/12)+L40,0) -> 14857757 | ... BL41: =IF(BL3<=Hypotheses!$D$72,BK41*(1+Hypotheses!$D$71/12)+BL40,0) -> 0
...

Sheet Scen_Central
B1: Scénario Central — compte de résultat et trésorerie mensuels (FCFA HT)
B3: Mois n° | D3: =0 -> 0 | E3: =D3+1 -> 1 | F3: =E3+1 -> 2 | G3: =F3+1 -> 3 | H3: =G3+1 -> 4 | I3: =H3+1 -> 5 | J3: =I3+1 -> 6 | K3: =J3+1 -> 7 | L3: =K3+1 -> 8 | ... BL3: =BK3+1 -> 60
B4: Mois | D4: =DATE(YEAR(Hypotheses!$D$6),MONTH(Hypotheses!$D$6)-1,1) -> 47727 | E4: =DATE(YEAR(D4),MONTH(D4)+1,1) -> 47757 | F4: =DATE(YEAR(E4),MONTH(E4)+1,1) -> 47788 | G4: =DATE(YEAR(F4),MONTH(F4)+1,1) -> 47818 | H4: =DATE(YEAR(G4),MONTH(G4)+1,1) -> 47849 | I4: =DATE(YEAR(H4),MONTH(H4)+1,1) -> 47880 | J4: =DATE(YEAR(I4),MONTH(I4)+1,1) -> 47908 | K4: =DATE(YEAR(J4),MONTH(J4)+1,1) -> 47939 | L4: =DATE(YEAR(K4),MONTH(K4)+1,1) -> 47969 | ... BL4: =DATE(YEAR(BK4),MONTH(BK4)+1,1) -> 49553
B5: Année d'exploitation | E5: =INT((E3-1)/12)+1 -> 1 | F5: =INT((F3-1)/12)+1 -> 1 | G5: =INT((G3-1)/12)+1 -> 1 | H5: =INT((H3-1)/12)+1 -> 1 | I5: =INT((I3-1)/12)+1 -> 1 | J5: =INT((J3-1)/12)+1 -> 1 | K5: =INT((K3-1)/12)+1 -> 1 | L5: =INT((L3-1)/12)+1 -> 1 | ... BL5: =INT((BL3-1)/12)+1 -> 5
B6: Mois dans l'année | E6: =MOD(E3-1,12)+1 -> 1 | F6: =MOD(F3-1,12)+1 -> 2 | G6: =MOD(G3-1,12)+1 -> 3 | H6: =MOD(H3-1,12)+1 -> 4 | I6: =MOD(I3-1,12)+1 -> 5 | J6: =MOD(J3-1,12)+1 -> 6 | K6: =MOD(K3-1,12)+1 -> 7 | L6: =MOD(L3-1,12)+1 -> 8 | ... BL6: =MOD(BL3-1,12)+1 -> 12
B7: Activité
B8: Capacité | C8: kg/jour | E8: =Hypotheses!$E$15*IF(E3>=Hypotheses!$E$16,2,1) -> 320 | F8: =Hypotheses!$E$15*IF(F3>=Hypotheses!$E$16,2,1) -> 320 | G8: =Hypotheses!$E$15*IF(G3>=Hypotheses!$E$16,2,1) -> 320 | H8: =Hypotheses!$E$15*IF(H3>=Hypotheses!$E$16,2,1) -> 320 | I8: =Hypotheses!$E$15*IF(I3>=Hypotheses!$E$16,2,1) -> 320 | J8: =Hypotheses!$E$15*IF(J3>=Hypotheses!$E$16,2,1) -> 320 | K8: =Hypotheses!$E$15*IF(K3>=Hypotheses!$E$16,2,1) -> 320 | L8: =Hypotheses!$E$15*IF(L3>=Hypotheses!$E$16,2,1) -> 320 | ... BL8: =Hypotheses!$E$15*IF(BL3>=Hypotheses!$E$16,2,1) -> 640
B9: Volume traité | C9: kg/jour | E9: =MIN(E8,Hypotheses!$E$11+(Hypotheses!$E$12-Hypotheses!$E$11)*MIN(1,(E3-1)/MAX(1,Hypotheses!$E$13-1))+Hypotheses!$E$14*MAX(0,E3-Hypotheses!$E$13)) -> 60 | F9: =MIN(F8,Hypotheses!$E$11+(Hypotheses!$E$12-Hypotheses!$E$11)*MIN(1,(F3-1)/MAX(1,Hypotheses!$E$13-1))+Hypotheses!$E$14*MAX(0,F3-Hypotheses!$E$13)) -> 74.117647 | G9: =MIN(G8,Hypotheses!$E$11+(Hypotheses!$E$12-Hypotheses!$E$11)*MIN(1,(G3-1)/MAX(1,Hypotheses!$E$13-1))+Hypotheses!$E$14*MAX(0,G3-Hypotheses!$E$13)) -> 88.235294 | H9: =MIN(H8,Hypotheses!$E$11+(Hypotheses!$E$12-Hypotheses!$E$11)*MIN(1,(H3-1)/MAX(1,Hypotheses!$E$13-1))+Hypotheses!$E$14*MAX(0,H3-Hypotheses!$E$13)) -> 102.35294 | I9: =MIN(I8,Hypotheses!$E$11+(Hypotheses!$E$12-Hypotheses!$E$11)*MIN(1,(I3-1)/MAX(1,Hypotheses!$E$13-1))+Hypotheses!$E$14*MAX(0,I3-Hypotheses!$E$13)) -> 116.47059 | J9: =MIN(J8,Hypotheses!$E$11+(Hypotheses!$E$12-Hypotheses!$E$11)*MIN(1,(J3-1)/MAX(1,Hypotheses!$E$13-1))+Hypotheses!$E$14*MAX(0,J3-Hypotheses!$E$13)) -> 130.58824 | K9: =MIN(K8,Hypotheses!$E$11+(Hypotheses!$E$12-Hypotheses!$E$11)*MIN(1,(K3-1)/MAX(1,Hypotheses!$E$13-1))+Hypotheses!$E$14*MAX(0,K3-Hypotheses!$E$13)) -> 144.70588 | L9: =MIN(L8,Hypotheses!$E$11+(Hypotheses!$E$12-Hypotheses!$E$11)*MIN(1,(L3-1)/MAX(1,Hypotheses!$E$13-1))+Hypotheses!$E$14*MAX(0,L3-Hypotheses!$E$13)) -> 158.82353 | ... BL9: =MIN(BL8,Hypotheses!$E$11+(Hypotheses!$E$12-Hypotheses!$E$11)*MIN(1,(BL3-1)/MAX(1,Hypotheses!$E$13-1))+Hypotheses!$E$14*MAX(0,BL3-Hypotheses!$E$13)) -> 510
B10: Taux de charge | C10: % | E10: =IF(E8>0,E9/E8,0) -> 0.1875 | F10: =IF(F8>0,F9/F8,0) -> 0.23161765 | G10: =IF(G8>0,G9/G8,0) -> 0.27573529 | H10: =IF(H8>0,H9/H8,0) -> 0.31985294 | I10: =IF(I8>0,I9/I8,0) -> 0.36397059 | J10: =IF(J8>0,J9/J8,0) -> 0.40808824 | K10: =IF(K8>0,K9/K8,0) -> 0.45220588 | L10: =IF(L8>0,L9/L8,0) -> 0.49632353 | ... BL10: =IF(BL8>0,BL9/BL8,0) -> 0.796875
B11: Volume mensuel | C11: kg/mois | E11: =E9*Hypotheses!$E$17 -> 1560 | F11: =F9*Hypotheses!$E$17 -> 1927.0588 | G11: =G9*Hypotheses!$E$17 -> 2294.1176 | H11: =H9*Hypotheses!$E$17 -> 2661.1765 | I11: =I9*Hypotheses!$E$17 -> 3028.2353 | J11: =J9*Hypotheses!$E$17 -> 3395.2941 | K11: =K9*Hypotheses!$E$17 -> 3762.3529 | L11: =L9*Hypotheses!$E$17 -> 4129.4118 | ... BL11: =BL9*Hypotheses!$E$17 -> 13260
B12: Part de location | C12: % | E12: =Hypotheses!$E$21*MIN(1,(E3-1)/47) -> 0 | F12: =Hypotheses!$E$21*MIN(1,(F3-1)/47) -> 0.010638298 | G12: =Hypotheses!$E$21*MIN(1,(G3-1)/47) -> 0.021276596 | H12: =Hypotheses!$E$21*MIN(1,(H3-1)/47) -> 0.031914894 | I12: =Hypotheses!$E$21*MIN(1,(I3-1)/47) -> 0.042553191 | J12: =Hypotheses!$E$21*MIN(1,(J3-1)/47) -> 0.053191489 | K12: =Hypotheses!$E$21*MIN(1,(K3-1)/47) -> 0.063829787 | L12: =Hypotheses!$E$21*MIN(1,(L3-1)/47) -> 0.074468085 | ... BL12: =Hypotheses!$E$21*MIN(1,(BL3-1)/47) -> 0.5
B13: dont Setal Entretien | C13: kg/mois | E13: =E11*(1-E12) -> 1560 | F13: =F11*(1-F12) -> 1906.5582 | G13: =G11*(1-G12) -> 2245.3066 | H13: =H11*(1-H12) -> 2576.2453 | I13: =I11*(1-I12) -> 2899.3742 | J13: =J11*(1-J12) -> 3214.6934 | K13: =K11*(1-K12) -> 3522.2028 | L13: =L11*(1-L12) -> 3821.9024 | ... BL13: =BL11*(1-BL12) -> 6630
B14: dont Setal Location | C14: kg/mois | E14: =E11*E12 -> 0 | F14: =F11*F12 -> 20.500626 | G14: =G11*G12 -> 48.811014 | H14: =H11*H12 -> 84.931164 | I14: =I11*I12 -> 128.86108 | J14: =J11*J12 -> 180.60075 | K14: =K11*K12 -> 240.15019 | L14: =L11*L12 -> 307.50939 | ... BL14: =BL11*BL12 -> 6630
B15: Compte de résultat
B16: CA Setal Entretien | C16: FCFA | E16: =E13*Hypotheses!$E$19 -> 1092000 | F16: =F13*Hypotheses!$E$19 -> 1334590.7 | G16: =G13*Hypotheses!$E$19 -> 1571714.6 | H16: =H13*Hypotheses!$E$19 -> 1803371.7 | I16: =I13*Hypotheses!$E$19 -> 2029562 | J16: =J13*Hypotheses!$E$19 -> 2250285.4 | K16: =K13*Hypotheses!$E$19 -> 2465541.9 | L16: =L13*Hypotheses!$E$19 -> 2675331.7 | ... BL16: =BL13*Hypotheses!$E$19 -> 4641000
B17: CA Setal Location | C17: FCFA | E17: =E14*Hypotheses!$E$20 -> 0 | F17: =F14*Hypotheses!$E$20 -> 22550.688 | G17: =G14*Hypotheses!$E$20 -> 53692.115 | H17: =H14*Hypotheses!$E$20 -> 93424.28 | I17: =I14*Hypotheses!$E$20 -> 141747.18 | J17: =J14*Hypotheses!$E$20 -> 198660.83 | K17: =K14*Hypotheses!$E$20 -> 264165.21 | L17: =L14*Hypotheses!$E$20 -> 338260.33 | ... BL17: =BL14*Hypotheses!$E$20 -> 7293000
B18: Chiffre d'affaires | C18: FCFA | E18: =E16+E17 -> 1092000 | F18: =F16+F17 -> 1357141.4 | G18: =G16+G17 -> 1625406.8 | H18: =H16+H17 -> 1896796 | I18: =I16+I17 -> 2171309.1 | J18: =J16+J17 -> 2448946.2 | K18: =K16+K17 -> 2729707.1 | L18: =L16+L17 -> 3013592 | ... BL18: =BL16+BL17 -> 11934000
B19: Consommables (eau, énergie, gaz, produits, emballages) | C19: FCFA | E19: =-E11*(Hypotheses!$E$23*Hypotheses!$E$24/1000+Hypotheses!$E$25*Hypotheses!$E$26+Hypotheses!$E$27+Hypotheses!$E$28+Hypotheses!$E$29+Hypotheses!$E$30) -> -354900 | F19: =-F11*(Hypotheses!$E$23*Hypotheses!$E$24/1000+Hypotheses!$E$25*Hypotheses!$E$26+Hypotheses!$E$27+Hypotheses!$E$28+Hypotheses!$E$29+Hypotheses!$E$30) -> -438405.88 | G19: =-G11*(Hypotheses!$E$23*Hypotheses!$E$24/1000+Hypotheses!$E$25*Hypotheses!$E$26+Hypotheses!$E$27+Hypotheses!$E$28+Hypotheses!$E$29+Hypotheses!$E$30) -> -521911.76 | H19: =-H11*(Hypotheses!$E$23*Hypotheses!$E$24/1000+Hypotheses!$E$25*Hypotheses!$E$26+Hypotheses!$E$27+Hypotheses!$E$28+Hypotheses!$E$29+Hypotheses!$E$30) -> -605417.65 | I19: =-I11*(Hypotheses!$E$23*Hypotheses!$E$24/1000+Hypotheses!$E$25*Hypotheses!$E$26+Hypotheses!$E$27+Hypotheses!$E$28+Hypotheses!$E$29+Hypotheses!$E$30) -> -688923.53 | J19: =-J11*(Hypotheses!$E$23*Hypotheses!$E$24/1000+Hypotheses!$E$25*Hypotheses!$E$26+Hypotheses!$E$27+Hypotheses!$E$28+Hypotheses!$E$29+Hypotheses!$E$30) -> -772429.41 | K19: =-K11*(Hypotheses!$E$23*Hypotheses!$E$24/1000+Hypotheses!$E$25*Hypotheses!$E$26+Hypotheses!$E$27+Hypotheses!$E$28+Hypotheses!$E$29+Hypotheses!$E$30) -> -855935.29 | L19: =-L11*(Hypotheses!$E$23*Hypotheses!$E$24/1000+Hypotheses!$E$25*Hypotheses!$E$26+Hypotheses!$E$27+Hypotheses!$E$28+Hypotheses!$E$29+Hypotheses!$E$30) -> -939441.18 | ... BL19: =-BL11*(Hypotheses!$E$23*Hypotheses!$E$24/1000+Hypotheses!$E$25*Hypotheses!$E$26+Hypotheses!$E$27+Hypotheses!$E$28+Hypotheses!$E$29+Hypotheses!$E$30) -> -3016650
B20: Stock de linge en location nécessaire | C20: FCFA | D20: =0 -> 0 | E20: =E14/Hypotheses!$E$17*Hypotheses!$E$33*Hypotheses!$E$32 -> 0 | F20: =F14/Hypotheses!$E$17*Hypotheses!$E$33*Hypotheses!$E$32 -> 24837.297 | G20: =G14/Hypotheses!$E$17*Hypotheses!$E$33*Hypotheses!$E$32 -> 59136.421 | H20: =H14/Hypotheses!$E$17*Hypotheses!$E$33*Hypotheses!$E$32 -> 102897.37 | I20: =I14/Hypotheses!$E$17*Hypotheses!$E$33*Hypotheses!$E$32 -> 156120.15 | J20: =J14/Hypotheses!$E$17*Hypotheses!$E$33*Hypotheses!$E$32 -> 218804.76 | K20: =K14/Hypotheses!$E$17*Hypotheses!$E$33*Hypotheses!$E$32 -> 290951.19 | L20: =L14/Hypotheses!$E$17*Hypotheses!$E$33*Hypotheses!$E$32 -> 372559.45 | ... BL20: =BL14/Hypotheses!$E$17*Hypotheses!$E$33*Hypotheses!$E$32 -> 8032500
B21: Usure et pertes du linge en location | C21: FCFA | E21: =-(E14/Hypotheses!$E$34*Hypotheses!$E$32+E20*Hypotheses!$E$35) -> 0 | F21: =-(F14/Hypotheses!$E$34*Hypotheses!$E$32+F20*Hypotheses!$E$35) -> -1478.4105 | G21: =-(G14/Hypotheses!$E$34*Hypotheses!$E$32+G20*Hypotheses!$E$35) -> -3520.025 | H21: =-(H14/Hypotheses!$E$34*Hypotheses!$E$32+H20*Hypotheses!$E$35) -> -6124.8436 | I21: =-(I14/Hypotheses!$E$34*Hypotheses!$E$32+I20*Hypotheses!$E$35) -> -9292.8661 | J21: =-(J14/Hypotheses!$E$34*Hypotheses!$E$32+J20*Hypotheses!$E$35) -> -13024.093 | K21: =-(K14/Hypotheses!$E$34*Hypotheses!$E$32+K20*Hypotheses!$E$35) -> -17318.523 | L21: =-(L14/Hypotheses!$E$34*Hypotheses!$E$32+L20*Hypotheses!$E$35) -> -22176.158 | ... BL21: =-(BL14/Hypotheses!$E$34*Hypotheses!$E$32+BL20*Hypotheses!$E$35) -> -478125
B22: Marge sur coûts variables | C22: FCFA | E22: =E18+E19+E21 -> 737100 | F22: =F18+F19+F21 -> 917257.13 | G22: =G18+G19+G21 -> 1099975 | H22: =H18+H19+H21 -> 1285253.5 | I22: =I18+I19+I21 -> 1473092.7 | J22: =J18+J19+J21 -> 1663492.7 | K22: =K18+K19+K21 -> 1856453.3 | L22: =L18+L19+L21 -> 2051974.7 | ... BL22: =BL18+BL19+BL21 -> 8439225
B23: Opérateurs | C23: personnes | E23: =IF(E9>=Hypotheses!$E$43,Hypotheses!$E$42,Hypotheses!$E$41)+IF(E3>=Hypotheses!$E$16,Hypotheses!$E$46,0) -> 2 | F23: =IF(F9>=Hypotheses!$E$43,Hypotheses!$E$42,Hypotheses!$E$41)+IF(F3>=Hypotheses!$E$16,Hypotheses!$E$46,0) -> 2 | G23: =IF(G9>=Hypotheses!$E$43,Hypotheses!$E$42,Hypotheses!$E$41)+IF(G3>=Hypotheses!$E$16,Hypotheses!$E$46,0) -> 2 | H23: =IF(H9>=Hypotheses!$E$43,Hypotheses!$E$42,Hypotheses!$E$41)+IF(H3>=Hypotheses!$E$16,Hypotheses!$E$46,0) -> 2 | I23: =IF(I9>=Hypotheses!$E$43,Hypotheses!$E$42,Hypotheses!$E$41)+IF(I3>=Hypotheses!$E$16,Hypotheses!$E$46,0) -> 2 | J23: =IF(J9>=Hypotheses!$E$43,Hypotheses!$E$42,Hypotheses!$E$41)+IF(J3>=Hypotheses!$E$16,Hypotheses!$E$46,0) -> 2 | K23: =IF(K9>=Hypotheses!$E$43,Hypotheses!$E$42,Hypotheses!$E$41)+IF(K3>=Hypotheses!$E$16,Hypotheses!$E$46,0) -> 2 | L23: =IF(L9>=Hypotheses!$E$43,Hypotheses!$E$42,Hypotheses!$E$41)+IF(L3>=Hypotheses!$E$16,Hypotheses!$E$46,0) -> 2 | ... BL23: =IF(BL9>=Hypotheses!$E$43,Hypotheses!$E$42,Hypotheses!$E$41)+IF(BL3>=Hypotheses!$E$16,Hypotheses!$E$46,0) -> 8
B24: 2e véhicule en service (1 = oui) | D24: =0 -> 0 | E24: =IF(OR(E9>=Hypotheses!$E$44,D24=1),1,0) -> 0 | F24: =IF(OR(F9>=Hypotheses!$E$44,E24=1),1,0) -> 0 | G24: =IF(OR(G9>=Hypotheses!$E$44,F24=1),1,0) -> 0 | H24: =IF(OR(H9>=Hypotheses!$E$44,G24=1),1,0) -> 0 | I24: =IF(OR(I9>=Hypotheses!$E$44,H24=1),1,0) -> 0 | J24: =IF(OR(J9>=Hypotheses!$E$44,I24=1),1,0) -> 0 | K24: =IF(OR(K9>=Hypotheses!$E$44,J24=1),1,0) -> 0 | L24: =IF(OR(L9>=Hypotheses!$E$44,K24=1),1,0) -> 0 | ... BL24: =IF(OR(BL9>=Hypotheses!$E$44,BK24=1),1,0) -> 1
B25: Salaires et charges sociales | C25: FCFA | E25: =-(Hypotheses!$E$37+Hypotheses!$E$39*(1+E24)+E23*Hypotheses!$E$38)*(1+Hypotheses!$E$40)*Hypotheses!$E$47/12 -> -713700 | F25: =-(Hypotheses!$E$37+Hypotheses!$E$39*(1+F24)+F23*Hypotheses!$E$38)*(1+Hypotheses!$E$40)*Hypotheses!$E$47/12 -> -713700 | G25: =-(Hypotheses!$E$37+Hypotheses!$E$39*(1+G24)+G23*Hypotheses!$E$38)*(1+Hypotheses!$E$40)*Hypotheses!$E$47/12 -> -713700 | H25: =-(Hypotheses!$E$37+Hypotheses!$E$39*(1+H24)+H23*Hypotheses!$E$38)*(1+Hypotheses!$E$40)*Hypotheses!$E$47/12 -> -713700 | I25: =-(Hypotheses!$E$37+Hypotheses!$E$39*(1+I24)+I23*Hypotheses!$E$38)*(1+Hypotheses!$E$40)*Hypotheses!$E$47/12 -> -713700 | J25: =-(Hypotheses!$E$37+Hypotheses!$E$39*(1+J24)+J23*Hypotheses!$E$38)*(1+Hypotheses!$E$40)*Hypotheses!$E$47/12 -> -713700 | K25: =-(Hypotheses!$E$37+Hypotheses!$E$39*(1+K24)+K23*Hypotheses!$E$38)*(1+Hypotheses!$E$40)*Hypotheses!$E$47/12 -> -713700 | L25: =-(Hypotheses!$E$37+Hypotheses!$E$39*(1+L24)+L23*Hypotheses!$E$38)*(1+Hypotheses!$E$40)*Hypotheses!$E$47/12 -> -713700 | ... BL25: =-(Hypotheses!$E$37+Hypotheses!$E$39*(1+BL24)+BL23*Hypotheses!$E$38)*(1+Hypotheses!$E$40)*Hypotheses!$E$47/12 -> -1718166.7
B26: Loyer | C26: FCFA | E26: =-Hypotheses!$E$49*Hypotheses!$E$50 -> -450000 | F26: =-Hypotheses!$E$49*Hypotheses!$E$50 -> -450000 | G26: =-Hypotheses!$E$49*Hypotheses!$E$50 -> -450000 | H26: =-Hypotheses!$E$49*Hypotheses!$E$50 -> -450000 | I26: =-Hypotheses!$E$49*Hypotheses!$E$50 -> -450000 | J26: =-Hypotheses!$E$49*Hypotheses!$E$50 -> -450000 | K26: =-Hypotheses!$E$49*Hypotheses!$E$50 -> -450000 | L26: =-Hypotheses!$E$49*Hypotheses!$E$50 -> -450000 | ... BL26: =-Hypotheses!$E$49*Hypotheses!$E$50 -> -450000
B27: Autres charges fixes (véhicule, assurances, maintenance, comptable, télécom, marketing, divers, abonnements) | C27: FCFA | E27: =-(Hypotheses!$E$51*(1+E24)+Investissements!$E$18*(1+Hypotheses!$E$60)*(Hypotheses!$E$52+Hypotheses!$E$53)/12+Hypotheses!$E$54+Hypotheses!$E$55+Hypotheses!$E$56+Hypotheses!$E$57+Hypotheses!$E$58) -> -970156.25 | F27: =-(Hypotheses!$E$51*(1+F24)+Investissements!$E$18*(1+Hypotheses!$E$60)*(Hypotheses!$E$52+Hypotheses!$E$53)/12+Hypotheses!$E$54+Hypotheses!$E$55+Hypotheses!$E$56+Hypotheses!$E$57+Hypotheses!$E$58) -> -970156.25 | G27: =-(Hypotheses!$E$51*(1+G24)+Investissements!$E$18*(1+Hypotheses!$E$60)*(Hypotheses!$E$52+Hypotheses!$E$53)/12+Hypotheses!$E$54+Hypotheses!$E$55+Hypotheses!$E$56+Hypotheses!$E$57+Hypotheses!$E$58) -> -970156.25 | H27: =-(Hypotheses!$E$51*(1+H24)+Investissements!$E$18*(1+Hypotheses!$E$60)*(Hypotheses!$E$52+Hypotheses!$E$53)/12+Hypotheses!$E$54+Hypotheses!$E$55+Hypotheses!$E$56+Hypotheses!$E$57+Hypotheses!$E$58) -> -970156.25 | I27: =-(Hypotheses!$E$51*(1+I24)+Investissements!$E$18*(1+Hypotheses!$E$60)*(Hypotheses!$E$52+Hypotheses!$E$53)/12+Hypotheses!$E$54+Hypotheses!$E$55+Hypotheses!$E$56+Hypotheses!$E$57+Hypotheses!$E$58) -> -970156.25 | J27: =-(Hypotheses!$E$51*(1+J24)+Investissements!$E$18*(1+Hypotheses!$E$60)*(Hypotheses!$E$52+Hypotheses!$E$53)/12+Hypotheses!$E$54+Hypotheses!$E$55+Hypotheses!$E$56+Hypotheses!$E$57+Hypotheses!$E$58) -> -970156.25 | K27: =-(Hypotheses!$E$51*(1+K24)+Investissements!$E$18*(1+Hypotheses!$E$60)*(Hypotheses!$E$52+Hypotheses!$E$53)/12+Hypotheses!$E$54+Hypotheses!$E$55+Hypotheses!$E$56+Hypotheses!$E$57+Hypotheses!$E$58) -> -970156.25 | L27: =-(Hypotheses!$E$51*(1+L24)+Investissements!$E$18*(1+Hypotheses!$E$60)*(Hypotheses!$E$52+Hypotheses!$E$53)/12+Hypotheses!$E$54+Hypotheses!$E$55+Hypotheses!$E$56+Hypotheses!$E$57+Hypotheses!$E$58) -> -970156.25 | ... BL27: =-(Hypotheses!$E$51*(1+BL24)+Investissements!$E$18*(1+Hypotheses!$E$60)*(Hypotheses!$E$52+Hypotheses!$E$53)/12+Hypotheses!$E$54+Hypotheses!$E$55+Hypotheses!$E$56+Hypotheses!$E$57+Hypotheses!$E$58) -> -1320156.2
B28: Frais avant ouverture | C28: FCFA | D28: =-Hypotheses!$E$61 -> -3000000 | E28: =0 -> 0 | F28: =0 -> 0 | G28: =0 -> 0 | H28: =0 -> 0 | I28: =0 -> 0 | J28: =0 -> 0 | K28: =0 -> 0 | L28: =0 -> 0 | ... BL28: =0 -> 0
B29: EBE (EBITDA) | C29: FCFA | D29: =D28 -> -3000000 | E29: =E22+E25+E26+E27+E28 -> -1396756.2 | F29: =F22+F25+F26+F27+F28 -> -1216599.1 | G29: =G22+G25+G26+G27+G28 -> -1033881.3 | H29: =H22+H25+H26+H27+H28 -> -848602.75 | I29: =I22+I25+I26+I27+I28 -> -660763.51 | J29: =J22+J25+J26+J27+J28 -> -470363.57 | K29: =K22+K25+K26+K27+K28 -> -277402.93 | L29: =L22+L25+L26+L27+L28 -> -81881.594 | ... BL29: =BL22+BL25+BL26+BL27+BL28 -> 4950902.1
