Workbook
Name LST_LIGNES: OFFSET(PARAMETRES!$I$7,0,0,MAX(1,COUNTA(PARAMETRES!$I$7:$I$36)),1)
Name LST_EQUIPES: OFFSET(PARAMETRES!$J$7,0,0,MAX(1,COUNTA(PARAMETRES!$J$7:$J$36)),1)
Name LST_PILOTES: OFFSET(PARAMETRES!$K$7,0,0,MAX(1,COUNTA(PARAMETRES!$K$7:$K$36)),1)
Name LST_PRODUITS: OFFSET(PARAMETRES!$M$7,0,0,MAX(1,COUNTA(PARAMETRES!$M$7:$M$36)),1)
Name LST_CAUSES: OFFSET(PARAMETRES!$R$7,0,0,MAX(1,COUNTA(PARAMETRES!$R$7:$R$46)),1)
Name LST_POSTES: OFFSET(PARAMETRES!$X$7,0,0,MAX(1,COUNTA(PARAMETRES!$X$7:$X$26)),1)
Name LST_FAM5M: OFFSET(PARAMETRES!$AB$7,0,0,MAX(1,COUNTA(PARAMETRES!$AB$7:$AB$26)),1)
Name LST_SOURCES: OFFSET(PARAMETRES!$AC$7,0,0,MAX(1,COUNTA(PARAMETRES!$AC$7:$AC$26)),1)
Name LST_NATURES: OFFSET(PARAMETRES!$AD$7,0,0,MAX(1,COUNTA(PARAMETRES!$AD$7:$AD$26)),1)
Name LST_STATUTS: OFFSET(PARAMETRES!$AE$7,0,0,MAX(1,COUNTA(PARAMETRES!$AE$7:$AE$26)),1)
Name LST_EFFICACITE: OFFSET(PARAMETRES!$AF$7,0,0,MAX(1,COUNTA(PARAMETRES!$AF$7:$AF$26)),1)
Name LST_OUINON: OFFSET(PARAMETRES!$AG$7,0,0,MAX(1,COUNTA(PARAMETRES!$AG$7:$AG$26)),1)
Name LST_CONTROLE: OFFSET(PARAMETRES!$AH$7,0,0,MAX(1,COUNTA(PARAMETRES!$AH$7:$AH$26)),1)
Name LST_SQCDP: OFFSET(PARAMETRES!$AI$7,0,0,MAX(1,COUNTA(PARAMETRES!$AI$7:$AI$26)),1)
Name LST_F_LIGNES: OFFSET(PARAMETRES!$AJ$7,0,0,MAX(1,COUNTA(PARAMETRES!$AJ$7:$AJ$26)),1)
Name LST_F_EQUIPES: OFFSET(PARAMETRES!$AK$7,0,0,MAX(1,COUNTA(PARAMETRES!$AK$7:$AK$26)),1)
Name LST_RUBRIQUES: OFFSET(PARAMETRES!$AL$7,0,0,MAX(1,COUNTA(PARAMETRES!$AL$7:$AL$26)),1)
Name LST_MOIS: OFFSET(PARAMETRES!$AM$7,0,0,MAX(1,COUNTA(PARAMETRES!$AM$7:$AM$26)),1)

Sheet LISEZ-MOI
A1: PILOTAGE DE LA PRODUCTION — MODE D'EMPLOI
A2: Classeur de pilotage opérationnel destiné au superviseur de production : saisie quotidienne, calcul normalisé du TRS, analyse des pertes et animation du plan d'actions.
A4: 1. ARCHITECTURE DU CLASSEUR
A5: Onglet | B5: Rôle
A6: COCKPIT | B6: Tableau de bord de la revue de performance : 12 indicateurs, 7 graphiques, top 5 des causes. | G6: Quotidienne (lecture) | I6: Superviseur | K6: Aucune saisie sauf les filtres et le bloc de décisions
A7: SAISIE_PROD | B7: Journal de production : une ligne par jour, par équipe et par ligne. Calcule le TRS et ses composantes. | G7: Quotidienne (5 min) | I7: Superviseur de poste | K7: Colonnes jaunes uniquement
A8: ARRETS | B8: Journal événementiel des arrêts : horaire, durée, code cause, famille 5M. Base de l'analyse de Pareto. | G8: À chaque arrêt | I8: Chef d'équipe | K8: Colonnes jaunes uniquement
A9: PLAN_ACTIONS | B9: Plan d'actions structuré : fait mesuré, cotation de criticité, cause racine, pilote, vérification d'efficacité. | G9: À chaque écart | I9: Superviseur / pilotes | K9: Colonnes jaunes uniquement
A10: POLYVALENCE | B10: Matrice de compétences ILUO et couverture des postes : risque de mono-compétence, plan de formation. | G10: Mensuelle | I10: Responsable de production | K10: Niveaux 0 à 4 et informations collaborateur
A11: AUDIT_5S | B11: Grille d'audit 5S pondérée : 25 critères, score par domaine, comparaison à l'audit précédent, historique. | G11: Mensuelle | I11: Auditeur désigné | K11: Pondérations, notes, constats et actions
A12: PRISE_DE_POSTE | B12: Standard de prise de poste et de passation SQCDP, matrice d'escalade et visa. | G12: À chaque relève | I12: Superviseur entrant / sortant | K12: Statuts, constats, actions et passation
A13: PARAMETRES | B13: Référentiels du site : objectifs et seuils, lignes, équipes, produits, causes d'arrêt, postes, listes de choix. | G13: À la mise en service, puis à chaque évolution | I13: Responsable de production | K13: Toutes les cellules bleues
A14: GLOSSAIRE | B14: Définition, formule et interprétation de chaque indicateur ; règles de gestion du classeur. | G14: Référence | I14: — | K14: Aucune
A15: CALC | B15: Moteur de calcul : agrégations filtrées, séries journalières, Pareto, cascade, historique 13 mois. | G15: Automatique | I15: — | K15: Aucune — ne pas modifier
A17: 2. LÉGENDE DES COULEURS
B18: Cellule à saisir | E18: Fond jaune, texte bleu : donnée saisie par l'utilisateur.
B19: Cellule calculée | E19: Fond bleu clair, texte noir : formule, ne pas écraser.
B20: Lien vers un référentiel | E20: Fond vert clair, texte vert : valeur reprise de l'onglet PARAMETRES.
B21: Objectif atteint | E21: La valeur est au niveau de la cible ou au-delà.
B22: Vigilance | E22: La valeur est entre la cible et le seuil d'alerte.
B23: Alerte | E23: La valeur a franchi le seuil d'alerte : action requise le jour même.
A25: 3. RITUEL DE MANAGEMENT
A26: Échéance | C26: Contenu
A27: Chaque fin de poste | C27: 5 min | D27: Saisir la ligne du jour dans SAISIE_PROD et les arrêts dans ARRETS ; vérifier la colonne de contrôle de cohérence.
A28: Chaque matin | C28: 5 min | D28: Lire le COCKPIT devant l'équipe : une carte rouge = une action ouverte le jour même dans PLAN_ACTIONS.
A29: Chaque semaine | C29: 30 min | D29: Revue du Pareto et de la cascade des pertes : choisir le chantier prioritaire, vérifier l'avancement des actions.
A30: Chaque mois | C30: 60 min | D30: Revue de performance : tendance 13 mois, audit 5S, matrice de polyvalence, efficacité des actions soldées.
A31: Chaque trimestre | C31: — | D31: Révision des objectifs et des seuils d'alerte dans PARAMETRES au regard des résultats obtenus.
A33: 4. MISE EN SERVICE — à réaliser avant la première saisie
A34: 1. Ouvrir l'onglet PARAMETRES et renseigner l'identification du site (cellules bleues).
A35: 2. Ajuster les objectifs et les seuils d'alerte au contrat de performance de l'entité.
A36: 3. Saisir les lignes de production, les équipes, les pilotes et les postes de travail.
A37: 4. Compléter le référentiel produits : chaque référence doit porter sa cadence nominale en pièces/minute, sans laquelle le taux de performance ne peut pas être calculé.
A38: 5. Adapter si besoin le référentiel des causes d'arrêt : conserver la colonne « Rubrique de saisie », qui relie chaque code à la colonne correspondante de SAISIE_PROD.
A39: 6. Supprimer le jeu de démonstration : sélectionner les lignes 5 à 46 de SAISIE_PROD, les lignes 5 à 203 de ARRETS et les lignes 9 à 16 de PLAN_ACTIONS, puis effacer uniquement le contenu des colonnes jaunes (touche Suppr). Ne jamais supprimer les lignes elles-mêmes : les formules des colonnes calculées seraient perdues.
A40: 7. Dans le COCKPIT, positionner l'année et le mois de travail, puis démarrer la saisie quotidienne.
A42: 5. JEU DE DÉMONSTRATION LIVRÉ AVEC LE CLASSEUR
A43: Le classeur est livré avec un mois complet de données fictives (janvier 2026, deux lignes de production, 42 journées de production, 199 arrêts horodatés, 8 actions correctives, 12 collaborateurs et un audit 5S). Ces données sont cohérentes entre elles — les arrêts du journal alimentent exactement les rubriques de perte de la saisie — afin que le cockpit soit immédiatement lisible et que chaque calcul puisse être vérifié. Elles n'ont aucune valeur métier et doivent être effacées avant la mise en service réelle (voir étape 6 ci-dessus). Le compteur « actions en retard » se calcule par rapport à la date du jour : les actions de démonstration, datées de janvier 2026, apparaissent donc en retard dès que le fichier est ouvert plus tard dans l'année.

Sheet COCKPIT
A1: COCKPIT DE PILOTAGE DE LA PRODUCTION
A2: =PARAMETRES!$C$5&" — "&PARAMETRES!$C$6&" | Revue quotidienne de performance | Édition du "&TEXT(TODAY(),"dd/mm/yyyy")
A4: Année : | B4: 2026 | C4: Mois : | D4: 1 | E4: =INDEX(PARAMETRES!$AM$7:$AM$18,$D$4)&" "&TEXT($B$4,"0000") | G4: Ligne : | H4: Toutes | J4: Équipe : | K4: Toutes | N4: ="Jours de production saisis : "&CALC!$B$9&" | Lignes suivies : "&COUNTIF(CALC!$D$72:$D$76,">0")
T5: Bloc technique — pilotage des couleurs (ne pas modifier)
A6: TRS DU MOIS (rendement synthétique) | D6: DISPONIBILITÉ | G6: PERFORMANCE (tenue de cadence) | J6: QUALITÉ AU PREMIER PASSAGE | M6: TRG (sur temps d'ouverture) | P6: TAUX DE SERVICE | T6: TRS | U6: =A7 | V6: =INDEX(PARAMETRES!$D$16:$D$29,MATCH("TRS",PARAMETRES!$A$16:$A$29,0)) | W6: =INDEX(PARAMETRES!$E$16:$E$29,MATCH("TRS",PARAMETRES!$A$16:$A$29,0)) | X6: =INDEX(PARAMETRES!$F$16:$F$29,MATCH("TRS",PARAMETRES!$A$16:$A$29,0)) | Y6: =IF($U6="","",IF($X6=1,IF($U6>=$V6,1,IF($U6<$W6,3,2)),IF($U6<=$V6,1,IF($U6>$W6,3,2))))
A7: =IFERROR(CALC!$V$20/CALC!$V$18,"") | D7: =IFERROR(CALC!$V$19/CALC!$V$18,"") | G7: =IFERROR((CALC!$V$19-CALC!$V$16)/CALC!$V$19,"") | J7: =IFERROR(CALC!$V$23/CALC!$V$22,"") | M7: =IFERROR(CALC!$V$20/CALC!$V$8,"") | P7: =IFERROR((CALC!$V$23+CALC!$V$24)/CALC!$V$25,"") | T7: DISPO | U7: =D7 | V7: =INDEX(PARAMETRES!$D$16:$D$29,MATCH("DISPO",PARAMETRES!$A$16:$A$29,0)) | W7: =INDEX(PARAMETRES!$E$16:$E$29,MATCH("DISPO",PARAMETRES!$A$16:$A$29,0)) | X7: =INDEX(PARAMETRES!$F$16:$F$29,MATCH("DISPO",PARAMETRES!$A$16:$A$29,0)) | Y7: =IF($U7="","",IF($X7=1,IF($U7>=$V7,1,IF($U7<$W7,3,2)),IF($U7<=$V7,1,IF($U7>$W7,3,2))))
T8: PERF | U8: =G7 | V8: =INDEX(PARAMETRES!$D$16:$D$29,MATCH("PERF",PARAMETRES!$A$16:$A$29,0)) | W8: =INDEX(PARAMETRES!$E$16:$E$29,MATCH("PERF",PARAMETRES!$A$16:$A$29,0)) | X8: =INDEX(PARAMETRES!$F$16:$F$29,MATCH("PERF",PARAMETRES!$A$16:$A$29,0)) | Y8: =IF($U8="","",IF($X8=1,IF($U8>=$V8,1,IF($U8<$W8,3,2)),IF($U8<=$V8,1,IF($U8>$W8,3,2))))
A9: ="Cible : "&TEXT($V$6,"0.0%") | D9: ="Cible : "&TEXT($V$7,"0.0%") | G9: ="Cible : "&TEXT($V$8,"0.0%") | J9: ="Cible : "&TEXT($V$9,"0.0%") | M9: ="Cible : "&TEXT($V$10,"0.0%") | P9: ="Cible : "&TEXT($V$11,"0.0%") | T9: QUAL | U9: =J7 | V9: =INDEX(PARAMETRES!$D$16:$D$29,MATCH("QUAL",PARAMETRES!$A$16:$A$29,0)) | W9: =INDEX(PARAMETRES!$E$16:$E$29,MATCH("QUAL",PARAMETRES!$A$16:$A$29,0)) | X9: =INDEX(PARAMETRES!$F$16:$F$29,MATCH("QUAL",PARAMETRES!$A$16:$A$29,0)) | Y9: =IF($U9="","",IF($X9=1,IF($U9>=$V9,1,IF($U9<$W9,3,2)),IF($U9<=$V9,1,IF($U9>$W9,3,2))))
A10: =IF(CALC!$L$99="","Mois précédent : non disponible","M-1 : "&TEXT(CALC!$L$99,"0.0%")&" "&TEXT(($U$6-CALC!$L$99)*100,"+0.0 pt;-0.0 pt;0.0 pt")) | D10: =IF(CALC!$M$99="","Mois précédent : non disponible","M-1 : "&TEXT(CALC!$M$99,"0.0%")&" "&TEXT(($U$7-CALC!$M$99)*100,"+0.0 pt;-0.0 pt;0.0 pt")) | G10: =IF(CALC!$N$99="","Mois précédent : non disponible","M-1 : "&TEXT(CALC!$N$99,"0.0%")&" "&TEXT(($U$8-CALC!$N$99)*100,"+0.0 pt;-0.0 pt;0.0 pt")) | J10: =IF(CALC!$O$99="","Mois précédent : non disponible","M-1 : "&TEXT(CALC!$O$99,"0.0%")&" "&TEXT(($U$9-CALC!$O$99)*100,"+0.0 pt;-0.0 pt;0.0 pt")) | M10: =IF(CALC!$P$99="","Mois précédent : non disponible","M-1 : "&TEXT(CALC!$P$99,"0.0%")&" "&TEXT(($U$10-CALC!$P$99)*100,"+0.0 pt;-0.0 pt;0.0 pt")) | P10: =IF(CALC!$Q$99="","Mois précédent : non disponible","M-1 : "&TEXT(CALC!$Q$99,"0.0%")&" "&TEXT(($U$11-CALC!$Q$99)*100,"+0.0 pt;-0.0 pt;0.0 pt")) | T10: TRG | U10: =M7 | V10: =INDEX(PARAMETRES!$D$16:$D$29,MATCH("TRG",PARAMETRES!$A$16:$A$29,0)) | W10: =INDEX(PARAMETRES!$E$16:$E$29,MATCH("TRG",PARAMETRES!$A$16:$A$29,0)) | X10: =INDEX(PARAMETRES!$F$16:$F$29,MATCH("TRG",PARAMETRES!$A$16:$A$29,0)) | Y10: =IF($U10="","",IF($X10=1,IF($U10>=$V10,1,IF($U10<$W10,3,2)),IF($U10<=$V10,1,IF($U10>$W10,3,2))))
T11: SERVICE | U11: =P7 | V11: =INDEX(PARAMETRES!$D$16:$D$29,MATCH("SERVICE",PARAMETRES!$A$16:$A$29,0)) | W11: =INDEX(PARAMETRES!$E$16:$E$29,MATCH("SERVICE",PARAMETRES!$A$16:$A$29,0)) | X11: =INDEX(PARAMETRES!$F$16:$F$29,MATCH("SERVICE",PARAMETRES!$A$16:$A$29,0)) | Y11: =IF($U11="","",IF($X11=1,IF($U11>=$V11,1,IF($U11<$W11,3,2)),IF($U11<=$V11,1,IF($U11>$W11,3,2))))
A12: NON-CONFORMITÉS INTERNES | D12: TAUX DE PRÉSENCE | G12: ACCIDENTS AVEC ARRÊT | J12: MTBF (temps entre pannes) | M12: MTTR (temps de réparation) | P12: ACTIONS EN RETARD | T12: PPM | U12: =A13 | V12: =INDEX(PARAMETRES!$D$16:$D$29,MATCH("PPM",PARAMETRES!$A$16:$A$29,0)) | W12: =INDEX(PARAMETRES!$E$16:$E$29,MATCH("PPM",PARAMETRES!$A$16:$A$29,0)) | X12: =INDEX(PARAMETRES!$F$16:$F$29,MATCH("PPM",PARAMETRES!$A$16:$A$29,0)) | Y12: =IF($U12="","",IF($X12=1,IF($U12>=$V12,1,IF($U12<$W12,3,2)),IF($U12<=$V12,1,IF($U12>$W12,3,2))))
A13: =IFERROR((CALC!$V$22-CALC!$V$23)/CALC!$V$22*1000000,"") | D13: =IFERROR(CALC!$V$29/CALC!$V$28,"") | G13: =CALC!$V$26 | J13: =IFERROR(CALC!$V$19/CALC!$V$27,"") | M13: =IFERROR(CALC!$V$10/CALC!$V$27,"") | P13: =PLAN_ACTIONS!$D$6 | T13: PRESENCE | U13: =D13 | V13: =INDEX(PARAMETRES!$D$16:$D$29,MATCH("PRESENCE",PARAMETRES!$A$16:$A$29,0)) | W13: =INDEX(PARAMETRES!$E$16:$E$29,MATCH("PRESENCE",PARAMETRES!$A$16:$A$29,0)) | X13: =INDEX(PARAMETRES!$F$16:$F$29,MATCH("PRESENCE",PARAMETRES!$A$16:$A$29,0)) | Y13: =IF($U13="","",IF($X13=1,IF($U13>=$V13,1,IF($U13<$W13,3,2)),IF($U13<=$V13,1,IF($U13>$W13,3,2))))
T14: ACCIDENT | U14: =G13 | V14: =INDEX(PARAMETRES!$D$16:$D$29,MATCH("ACCIDENT",PARAMETRES!$A$16:$A$29,0)) | W14: =INDEX(PARAMETRES!$E$16:$E$29,MATCH("ACCIDENT",PARAMETRES!$A$16:$A$29,0)) | X14: =INDEX(PARAMETRES!$F$16:$F$29,MATCH("ACCIDENT",PARAMETRES!$A$16:$A$29,0)) | Y14: =IF($U14="","",IF($X14=1,IF($U14>=$V14,1,IF($U14<$W14,3,2)),IF($U14<=$V14,1,IF($U14>$W14,3,2))))
A15: ="Cible : "&TEXT($V$12,"#,##0")&" ppm" | D15: ="Cible : "&TEXT($V$13,"0.0%") | G15: ="Cible : "&TEXT($V$14,"0") | J15: ="Cible : "&TEXT($V$15,"#,##0")&" min" | M15: ="Cible : "&TEXT($V$16,"#,##0")&" min" | P15: ="Cible : "&TEXT($V$17,"0") | T15: MTBF | U15: =J13 | V15: =INDEX(PARAMETRES!$D$16:$D$29,MATCH("MTBF",PARAMETRES!$A$16:$A$29,0)) | W15: =INDEX(PARAMETRES!$E$16:$E$29,MATCH("MTBF",PARAMETRES!$A$16:$A$29,0)) | X15: =INDEX(PARAMETRES!$F$16:$F$29,MATCH("MTBF",PARAMETRES!$A$16:$A$29,0)) | Y15: =IF($U15="","",IF($X15=1,IF($U15>=$V15,1,IF($U15<$W15,3,2)),IF($U15<=$V15,1,IF($U15>$W15,3,2))))
A16: ="Seuil d'alerte : "&TEXT($W$12,"#,##0")&" ppm" | D16: ="Seuil d'alerte : "&TEXT($W$13,"0.0%") | G16: ="Seuil d'alerte : "&TEXT($W$14,"0") | J16: ="Seuil d'alerte : "&TEXT($W$15,"#,##0")&" min" | M16: ="Seuil d'alerte : "&TEXT($W$16,"#,##0")&" min" | P16: ="Seuil d'alerte : "&TEXT($W$17,"0") | T16: MTTR | U16: =M13 | V16: =INDEX(PARAMETRES!$D$16:$D$29,MATCH("MTTR",PARAMETRES!$A$16:$A$29,0)) | W16: =INDEX(PARAMETRES!$E$16:$E$29,MATCH("MTTR",PARAMETRES!$A$16:$A$29,0)) | X16: =INDEX(PARAMETRES!$F$16:$F$29,MATCH("MTTR",PARAMETRES!$A$16:$A$29,0)) | Y16: =IF($U16="","",IF($X16=1,IF($U16>=$V16,1,IF($U16<$W16,3,2)),IF($U16<=$V16,1,IF($U16>$W16,3,2))))
T17: RETARD | U17: =P13 | V17: =INDEX(PARAMETRES!$D$16:$D$29,MATCH("RETARD",PARAMETRES!$A$16:$A$29,0)) | W17: =INDEX(PARAMETRES!$E$16:$E$29,MATCH("RETARD",PARAMETRES!$A$16:$A$29,0)) | X17: =INDEX(PARAMETRES!$F$16:$F$29,MATCH("RETARD",PARAMETRES!$A$16:$A$29,0)) | Y17: =IF($U17="","",IF($X17=1,IF($U17>=$V17,1,IF($U17<$W17,3,2)),IF($U17<=$V17,1,IF($U17>$W17,3,2))))
A18: ANALYSE DE LA PERFORMANCE DU MOIS
A78: TOP 5 DES CAUSES D'ARRÊT SUBI DU MOIS — source : journal des arrêts, hors arrêts planifiés
A79: Rang | C79: Code | E79: Cause d'arrêt | J79: Minutes perdues | L79: Occurrences | N79: Durée moyenne | P79: Part des arrêts subis
A80: =CALC!$A$152 | C80: =CALC!$B$152 | E80: =CALC!$C$152 | J80: =CALC!$D$152 | L80: =CALC!$E$152 | N80: =CALC!$F$152 | P80: =CALC!$G$152
A81: =CALC!$A$153 | C81: =CALC!$B$153 | E81: =CALC!$C$153 | J81: =CALC!$D$153 | L81: =CALC!$E$153 | N81: =CALC!$F$153 | P81: =CALC!$G$153
A82: =CALC!$A$154 | C82: =CALC!$B$154 | E82: =CALC!$C$154 | J82: =CALC!$D$154 | L82: =CALC!$E$154 | N82: =CALC!$F$154 | P82: =CALC!$G$154
A83: =CALC!$A$155 | C83: =CALC!$B$155 | E83: =CALC!$C$155 | J83: =CALC!$D$155 | L83: =CALC!$E$155 | N83: =CALC!$F$155 | P83: =CALC!$G$155
A84: =CALC!$A$156 | C84: =CALC!$B$156 | E84: =CALC!$C$156 | J84: =CALC!$D$156 | L84: =CALC!$E$156 | N84: =CALC!$F$156 | P84: =CALC!$G$156
A87: DÉCISIONS ET ENGAGEMENTS DE LA REVUE — à renseigner pendant l'animation
A88: Écart constaté (fait mesuré) | F88: Décision prise | L88: Pilote | N88: Échéance | P88: N° d'action associé
A95: Lecture des cartes : vert = cible atteinte • orange = entre la cible et le seuil d'alerte • rouge = au-delà du seuil d'alerte. Cibles et seuils sont définis dans l'onglet PARAMETRES. Règle d'animation : toute carte rouge donne lieu, le jour même, à une action ouverte dans le PLAN_ACTIONS avec un pilote nommé et une date cible. Le graphique de suivi journalier affiche la moyenne mobile 7 jours et les limites de contrôle (moyenne ± 2 écarts-types) : un point hors limite signale une cause spéciale à investiguer, à distinguer d'une variation courante du procédé.

Sheet SAISIE_PROD
A1: SAISIE QUOTIDIENNE DE PRODUCTION
A2: Une ligne par jour, par équipe et par ligne de production. Saisir uniquement les colonnes sur fond jaune (5 minutes en fin de poste) : les colonnes bleues sont calculées et alimentent le cockpit.
A3: IDENTIFICATION | F3: TEMPS D'OUVERTURE ET PERTES DE TEMPS (minutes) | O3: PRODUCTION ET QUALITÉ | U3: RESSOURCES ET SÉCURITÉ | Z3: ANALYSE DE L'ÉCART | AB3: INDICATEURS CALCULÉS — ne rien saisir
A4: Date | B4: Équipe | C4: Ligne / ressource | D4: N° d'OF / lot | E4: Référence produit | F4: Temps d'ouverture TO (min) | G4: Arrêts planifiés (min) | H4: Pannes (min) | I4: Changement de série (min) | J4: Réglages et micro-arrêts (min) | K4: Manque matière (min) | L4: Manque personnel (min) | M4: Autres arrêts subis (min) | N4: Nombre de pannes | O4: Cadence nominale (pcs/min) | P4: Qté produite | Q4: Qté conforme 1er passage | R4: Qté retouchée | S4: Qté rebutée | T4: Qté demandée (programme) | U4: Effectif prévu | V4: Effectif présent | W4: Heures supp. | X4: Accidents avec arrêt | Y4: Presqu'accidents et situations dang. | Z4: Code arrêt principal | AA4: Problème principal du poste | AB4: Temps requis TR (min) | AC4: Arrêts subis (min) | AD4: Temps de marche TF (min) | AE4: Temps utile TU (min) | AF4: Disponibilité | AG4: Performance | AH4: Qualité RFT | AI4: TRS | AJ4: TRG | AK4: MTBF (min) | AL4: MTTR (min) | AM4: Non-conformités (ppm) | AN4: Taux de service | AO4: Taux de présence | AP4: Perte de cadence (min) | AQ4: Perte non-qualité (min) | AR4: Contrôle de cohérence | AS4: Filtre cockpit
A5: 46024 | B5: Équipe A (matin) | C5: Ligne 1 - Assemblage | D5: OF-01001 | E5: REF-1001 | F5: 480 | G5: 40 | H5: 49 | I5: 32 | J5: 0 | K5: 0 | L5: 0 | M5: 0 | N5: 1 | O5: =IF($E5="","",IFERROR(INDEX(PARAMETRES!$O$7:$O$36,MATCH($E5,PARAMETRES!$M$7:$M$36,0)),"")) | P5: 4631 | Q5: 4547 | R5: 37 | S5: 47 | T5: 4982 | U5: 12 | V5: 11 | W5: 4 | X5: 0 | Y5: 1 | Z5: PAN-01 | AA5: Panne mécanique — Assemblage | AB5: =IF($A5="","",MAX(0,$F5-$G5)) | AC5: =IF($A5="","",SUM($H5:$M5)) | AD5: =IF($A5="","",MAX(0,$AB5-$AC5)) | AE5: =IF($A5="","",IFERROR($Q5/$O5,"")) | AF5: =IF($A5="","",IFERROR($AD5/$AB5,"")) | AG5: =IF($A5="","",IFERROR(($P5/$O5)/$AD5,"")) | AH5: =IF($A5="","",IFERROR($Q5/$P5,"")) | AI5: =IF($A5="","",IFERROR($AF5*$AG5*$AH5,"")) | AJ5: =IF($A5="","",IFERROR($AE5/$F5,"")) | AK5: =IF($A5="","",IFERROR($AD5/$N5,"")) | AL5: =IF($A5="","",IFERROR($H5/$N5,"")) | AM5: =IF($A5="","",IFERROR(($P5-$Q5)/$P5*1000000,"")) | AN5: =IF($A5="","",IFERROR(($Q5+$R5)/$T5,"")) | AO5: =IF($A5="","",IFERROR($V5/$U5,"")) | AP5: =IF($A5="","",IFERROR(MAX(0,$AD5-$P5/$O5),"")) | AQ5: =IF($A5="","",IFERROR(($P5-$Q5)/$O5,"")) | AR5: =IF($A5="","",IF($F5="","Temps d'ouverture manquant",IF($O5="","Cadence produit inconnue",IF($G5>$F5,"Arrêts planifiés > temps d'ouverture",IF($AC5>$AB5,"Arrêts subis > temps requis",IF($P5<>$Q5+$R5+$S5,"Produite ≠ conforme + retouchée + rebutée",IF($Q5>$P5,"Conforme > produite",IF($V5>$U5,"Présents > prévus","OK")))))))) | AS5: =IF($A5="",0,IF(AND(OR(COCKPIT!$H$4="Toutes",$C5=COCKPIT!$H$4),OR(COCKPIT!$K$4="Toutes",$B5=COCKPIT!$K$4)),1,0))
A6: 46024 | B6: Équipe B (après-midi) | C6: Ligne 2 - Usinage | D6: OF-01002 | E6: REF-2001 | F6: 480 | G6: 40 | H6: 0 | I6: 0 | J6: 14 | K6: 10 | L6: 0 | M6: 17 | N6: 0 | O6: =IF($E6="","",IFERROR(INDEX(PARAMETRES!$O$7:$O$36,MATCH($E6,PARAMETRES!$M$7:$M$36,0)),"")) | P6: 3339 | Q6: 3288 | R6: 22 | S6: 29 | T6: 3559 | U6: 8 | V6: 8 | W6: 0 | X6: 0 | Y6: 0 | Z6: LOG-01 | AA6: Attente cariste / évacuation en-cours — Usinage | AB6: =IF($A6="","",MAX(0,$F6-$G6)) | AC6: =IF($A6="","",SUM($H6:$M6)) | AD6: =IF($A6="","",MAX(0,$AB6-$AC6)) | AE6: =IF($A6="","",IFERROR($Q6/$O6,"")) | AF6: =IF($A6="","",IFERROR($AD6/$AB6,"")) | AG6: =IF($A6="","",IFERROR(($P6/$O6)/$AD6,"")) | AH6: =IF($A6="","",IFERROR($Q6/$P6,"")) | AI6: =IF($A6="","",IFERROR($AF6*$AG6*$AH6,"")) | AJ6: =IF($A6="","",IFERROR($AE6/$F6,"")) | AK6: =IF($A6="","",IFERROR($AD6/$N6,"")) | AL6: =IF($A6="","",IFERROR($H6/$N6,"")) | AM6: =IF($A6="","",IFERROR(($P6-$Q6)/$P6*1000000,"")) | AN6: =IF($A6="","",IFERROR(($Q6+$R6)/$T6,"")) | AO6: =IF($A6="","",IFERROR($V6/$U6,"")) | AP6: =IF($A6="","",IFERROR(MAX(0,$AD6-$P6/$O6),"")) | AQ6: =IF($A6="","",IFERROR(($P6-$Q6)/$O6,"")) | AR6: =IF($A6="","",IF($F6="","Temps d'ouverture manquant",IF($O6="","Cadence produit inconnue",IF($G6>$F6,"Arrêts planifiés > temps d'ouverture",IF($AC6>$AB6,"Arrêts subis > temps requis",IF($P6<>$Q6+$R6+$S6,"Produite ≠ conforme + retouchée + rebutée",IF($Q6>$P6,"Conforme > produite",IF($V6>$U6,"Présents > prévus","OK")))))))) | AS6: =IF($A6="",0,IF(AND(OR(COCKPIT!$H$4="Toutes",$C6=COCKPIT!$H$4),OR(COCKPIT!$K$4="Toutes",$B6=COCKPIT!$K$4)),1,0))
A7: 46027 | B7: Équipe B (après-midi) | C7: Ligne 1 - Assemblage | D7: OF-01003 | E7: REF-1002 | F7: 480 | G7: 40 | H7: 53 | I7: 0 | J7: 13 | K7: 19 | L7: 29 | M7: 15 | N7: 1 | O7: =IF($E7="","",IFERROR(INDEX(PARAMETRES!$O$7:$O$36,MATCH($E7,PARAMETRES!$M$7:$M$36,0)),"")) | P7: 3421 | Q7: 3376 | R7: 20 | S7: 25 | T7: 3430 | U7: 12 | V7: 12 | W7: 0 | X7: 0 | Y7: 0 | Z7: PAN-03 | AA7: Défaut automatisme / supervision — Assemblage | AB7: =IF($A7="","",MAX(0,$F7-$G7)) | AC7: =IF($A7="","",SUM($H7:$M7)) | AD7: =IF($A7="","",MAX(0,$AB7-$AC7)) | AE7: =IF($A7="","",IFERROR($Q7/$O7,"")) | AF7: =IF($A7="","",IFERROR($AD7/$AB7,"")) | AG7: =IF($A7="","",IFERROR(($P7/$O7)/$AD7,"")) | AH7: =IF($A7="","",IFERROR($Q7/$P7,"")) | AI7: =IF($A7="","",IFERROR($AF7*$AG7*$AH7,"")) | AJ7: =IF($A7="","",IFERROR($AE7/$F7,"")) | AK7: =IF($A7="","",IFERROR($AD7/$N7,"")) | AL7: =IF($A7="","",IFERROR($H7/$N7,"")) | AM7: =IF($A7="","",IFERROR(($P7-$Q7)/$P7*1000000,"")) | AN7: =IF($A7="","",IFERROR(($Q7+$R7)/$T7,"")) | AO7: =IF($A7="","",IFERROR($V7/$U7,"")) | AP7: =IF($A7="","",IFERROR(MAX(0,$AD7-$P7/$O7),"")) | AQ7: =IF($A7="","",IFERROR(($P7-$Q7)/$O7,"")) | AR7: =IF($A7="","",IF($F7="","Temps d'ouverture manquant",IF($O7="","Cadence produit inconnue",IF($G7>$F7,"Arrêts planifiés > temps d'ouverture",IF($AC7>$AB7,"Arrêts subis > temps requis",IF($P7<>$Q7+$R7+$S7,"Produite ≠ conforme + retouchée + rebutée",IF($Q7>$P7,"Conforme > produite",IF($V7>$U7,"Présents > prévus","OK")))))))) | AS7: =IF($A7="",0,IF(AND(OR(COCKPIT!$H$4="Toutes",$C7=COCKPIT!$H$4),OR(COCKPIT!$K$4="Toutes",$B7=COCKPIT!$K$4)),1,0))
A8: 46027 | B8: Équipe A (matin) | C8: Ligne 2 - Usinage | D8: OF-01004 | E8: REF-2002 | F8: 480 | G8: 40 | H8: 29 | I8: 0 | J8: 0 | K8: 0 | L8: 0 | M8: 9 | N8: 1 | O8: =IF($E8="","",IFERROR(INDEX(PARAMETRES!$O$7:$O$36,MATCH($E8,PARAMETRES!$M$7:$M$36,0)),"")) | P8: 2864 | Q8: 2835 | R8: 13 | S8: 16 | T8: 2848 | U8: 8 | V8: 8 | W8: 0 | X8: 0 | Y8: 0 | Z8: PAN-02 | AA8: Panne électrique ou capteur — Usinage | AB8: =IF($A8="","",MAX(0,$F8-$G8)) | AC8: =IF($A8="","",SUM($H8:$M8)) | AD8: =IF($A8="","",MAX(0,$AB8-$AC8)) | AE8: =IF($A8="","",IFERROR($Q8/$O8,"")) | AF8: =IF($A8="","",IFERROR($AD8/$AB8,"")) | AG8: =IF($A8="","",IFERROR(($P8/$O8)/$AD8,"")) | AH8: =IF($A8="","",IFERROR($Q8/$P8,"")) | AI8: =IF($A8="","",IFERROR($AF8*$AG8*$AH8,"")) | AJ8: =IF($A8="","",IFERROR($AE8/$F8,"")) | AK8: =IF($A8="","",IFERROR($AD8/$N8,"")) | AL8: =IF($A8="","",IFERROR($H8/$N8,"")) | AM8: =IF($A8="","",IFERROR(($P8-$Q8)/$P8*1000000,"")) | AN8: =IF($A8="","",IFERROR(($Q8+$R8)/$T8,"")) | AO8: =IF($A8="","",IFERROR($V8/$U8,"")) | AP8: =IF($A8="","",IFERROR(MAX(0,$AD8-$P8/$O8),"")) | AQ8: =IF($A8="","",IFERROR(($P8-$Q8)/$O8,"")) | AR8: =IF($A8="","",IF($F8="","Temps d'ouverture manquant",IF($O8="","Cadence produit inconnue",IF($G8>$F8,"Arrêts planifiés > temps d'ouverture",IF($AC8>$AB8,"Arrêts subis > temps requis",IF($P8<>$Q8+$R8+$S8,"Produite ≠ conforme + retouchée + rebutée",IF($Q8>$P8,"Conforme > produite",IF($V8>$U8,"Présents > prévus","OK")))))))) | AS8: =IF($A8="",0,IF(AND(OR(COCKPIT!$H$4="Toutes",$C8=COCKPIT!$H$4),OR(COCKPIT!$K$4="Toutes",$B8=COCKPIT!$K$4)),1,0))
A9: 46028 | B9: Équipe A (matin) | C9: Ligne 1 - Assemblage | D9: OF-01005 | E9: REF-1001 | F9: 480 | G9: 100 | H9: 26 | I9: 18 | J9: 14 | K9: 0 | L9: 15 | M9: 0 | N9: 1 | O9: =IF($E9="","",IFERROR(INDEX(PARAMETRES!$O$7:$O$36,MATCH($E9,PARAMETRES!$M$7:$M$36,0)),"")) | P9: 4144 | Q9: 4110 | R9: 15 | S9: 19 | T9: 4252 | U9: 12 | V9: 12 | W9: 0 | X9: 0 | Y9: 0 | Z9: PAN-01 | AA9: Panne mécanique — Assemblage | AB9: =IF($A9="","",MAX(0,$F9-$G9)) | AC9: =IF($A9="","",SUM($H9:$M9)) | AD9: =IF($A9="","",MAX(0,$AB9-$AC9)) | AE9: =IF($A9="","",IFERROR($Q9/$O9,"")) | AF9: =IF($A9="","",IFERROR($AD9/$AB9,"")) | AG9: =IF($A9="","",IFERROR(($P9/$O9)/$AD9,"")) | AH9: =IF($A9="","",IFERROR($Q9/$P9,"")) | AI9: =IF($A9="","",IFERROR($AF9*$AG9*$AH9,"")) | AJ9: =IF($A9="","",IFERROR($AE9/$F9,"")) | AK9: =IF($A9="","",IFERROR($AD9/$N9,"")) | AL9: =IF($A9="","",IFERROR($H9/$N9,"")) | AM9: =IF($A9="","",IFERROR(($P9-$Q9)/$P9*1000000,"")) | AN9: =IF($A9="","",IFERROR(($Q9+$R9)/$T9,"")) | AO9: =IF($A9="","",IFERROR($V9/$U9,"")) | AP9: =IF($A9="","",IFERROR(MAX(0,$AD9-$P9/$O9),"")) | AQ9: =IF($A9="","",IFERROR(($P9-$Q9)/$O9,"")) | AR9: =IF($A9="","",IF($F9="","Temps d'ouverture manquant",IF($O9="","Cadence produit inconnue",IF($G9>$F9,"Arrêts planifiés > temps d'ouverture",IF($AC9>$AB9,"Arrêts subis > temps requis",IF($P9<>$Q9+$R9+$S9,"Produite ≠ conforme + retouchée + rebutée",IF($Q9>$P9,"Conforme > produite",IF($V9>$U9,"Présents > prévus","OK")))))))) | AS9: =IF($A9="",0,IF(AND(OR(COCKPIT!$H$4="Toutes",$C9=COCKPIT!$H$4),OR(COCKPIT!$K$4="Toutes",$B9=COCKPIT!$K$4)),1,0))
A10: 46028 | B10: Équipe B (après-midi) | C10: Ligne 2 - Usinage | D10: OF-01006 | E10: REF-2001 | F10: 480 | G10: 100 | H10: 23 | I10: 35 | J10: 8 | K10: 17 | L10: 0 | M10: 9 | N10: 1 | O10: =IF($E10="","",IFERROR(INDEX(PARAMETRES!$O$7:$O$36,MATCH($E10,PARAMETRES!$M$7:$M$36,0)),"")) | P10: 2229 | Q10: 2217 | R10: 5 | S10: 7 | T10: 2267 | U10: 8 | V10: 7 | W10: 0 | X10: 0 | Y10: 0 | Z10: CDS-01 | AA10: Changement de série (outillage) — Usinage | AB10: =IF($A10="","",MAX(0,$F10-$G10)) | AC10: =IF($A10="","",SUM($H10:$M10)) | AD10: =IF($A10="","",MAX(0,$AB10-$AC10)) | AE10: =IF($A10="","",IFERROR($Q10/$O10,"")) | AF10: =IF($A10="","",IFERROR($AD10/$AB10,"")) | AG10: =IF($A10="","",IFERROR(($P10/$O10)/$AD10,"")) | AH10: =IF($A10="","",IFERROR($Q10/$P10,"")) | AI10: =IF($A10="","",IFERROR($AF10*$AG10*$AH10,"")) | AJ10: =IF($A10="","",IFERROR($AE10/$F10,"")) | AK10: =IF($A10="","",IFERROR($AD10/$N10,"")) | AL10: =IF($A10="","",IFERROR($H10/$N10,"")) | AM10: =IF($A10="","",IFERROR(($P10-$Q10)/$P10*1000000,"")) | AN10: =IF($A10="","",IFERROR(($Q10+$R10)/$T10,"")) | AO10: =IF($A10="","",IFERROR($V10/$U10,"")) | AP10: =IF($A10="","",IFERROR(MAX(0,$AD10-$P10/$O10),"")) | AQ10: =IF($A10="","",IFERROR(($P10-$Q10)/$O10,"")) | AR10: =IF($A10="","",IF($F10="","Temps d'ouverture manquant",IF($O10="","Cadence produit inconnue",IF($G10>$F10,"Arrêts planifiés > temps d'ouverture",IF($AC10>$AB10,"Arrêts subis > temps requis",IF($P10<>$Q10+$R10+$S10,"Produite ≠ conforme + retouchée + rebutée",IF($Q10>$P10,"Conforme > produite",IF($V10>$U10,"Présents > prévus","OK")))))))) | AS10: =IF($A10="",0,IF(AND(OR(COCKPIT!$H$4="Toutes",$C10=COCKPIT!$H$4),OR(COCKPIT!$K$4="Toutes",$B10=COCKPIT!$K$4)),1,0))
A11: 46029 | B11: Équipe B (après-midi) | C11: Ligne 1 - Assemblage | D11: OF-01007 | E11: REF-1002 | F11: 480 | G11: 40 | H11: 0 | I11: 0 | J11: 0 | K11: 16 | L11: 17 | M11: 9 | N11: 0 | O11: =IF($E11="","",IFERROR(INDEX(PARAMETRES!$O$7:$O$36,MATCH($E11,PARAMETRES!$M$7:$M$36,0)),"")) | P11: 4577 | Q11: 4499 | R11: 35 | S11: 43 | T11: 4772 | U11: 12 | V11: 12 | W11: 0 | X11: 0 | Y11: 0 | Z11: PER-02 | AA11: Accompagnement / montée en compétence — Assemblage | AB11: =IF($A11="","",MAX(0,$F11-$G11)) | AC11: =IF($A11="","",SUM($H11:$M11)) | AD11: =IF($A11="","",MAX(0,$AB11-$AC11)) | AE11: =IF($A11="","",IFERROR($Q11/$O11,"")) | AF11: =IF($A11="","",IFERROR($AD11/$AB11,"")) | AG11: =IF($A11="","",IFERROR(($P11/$O11)/$AD11,"")) | AH11: =IF($A11="","",IFERROR($Q11/$P11,"")) | AI11: =IF($A11="","",IFERROR($AF11*$AG11*$AH11,"")) | AJ11: =IF($A11="","",IFERROR($AE11/$F11,"")) | AK11: =IF($A11="","",IFERROR($AD11/$N11,"")) | AL11: =IF($A11="","",IFERROR($H11/$N11,"")) | AM11: =IF($A11="","",IFERROR(($P11-$Q11)/$P11*1000000,"")) | AN11: =IF($A11="","",IFERROR(($Q11+$R11)/$T11,"")) | AO11: =IF($A11="","",IFERROR($V11/$U11,"")) | AP11: =IF($A11="","",IFERROR(MAX(0,$AD11-$P11/$O11),"")) | AQ11: =IF($A11="","",IFERROR(($P11-$Q11)/$O11,"")) | AR11: =IF($A11="","",IF($F11="","Temps d'ouverture manquant",IF($O11="","Cadence produit inconnue",IF($G11>$F11,"Arrêts planifiés > temps d'ouverture",IF($AC11>$AB11,"Arrêts subis > temps requis",IF($P11<>$Q11+$R11+$S11,"Produite ≠ conforme + retouchée + rebutée",IF($Q11>$P11,"Conforme > produite",IF($V11>$U11,"Présents > prévus","OK")))))))) | AS11: =IF($A11="",0,IF(AND(OR(COCKPIT!$H$4="Toutes",$C11=COCKPIT!$H$4),OR(COCKPIT!$K$4="Toutes",$B11=COCKPIT!$K$4)),1,0))
A12: 46029 | B12: Équipe A (matin) | C12: Ligne 2 - Usinage | D12: OF-01008 | E12: REF-2002 | F12: 480 | G12: 40 | H12: 42 | I12: 17 | J12: 0 | K12: 12 | L12: 0 | M12: 9 | N12: 1 | O12: =IF($E12="","",IFERROR(INDEX(PARAMETRES!$O$7:$O$36,MATCH($E12,PARAMETRES!$M$7:$M$36,0)),"")) | P12: 2376 | Q12: 2342 | R12: 15 | S12: 19 | T12: 2455 | U12: 8 | V12: 8 | W12: 0 | X12: 0 | Y12: 0 | Z12: PAN-02 | AA12: Panne électrique ou capteur — Usinage | AB12: =IF($A12="","",MAX(0,$F12-$G12)) | AC12: =IF($A12="","",SUM($H12:$M12)) | AD12: =IF($A12="","",MAX(0,$AB12-$AC12)) | AE12: =IF($A12="","",IFERROR($Q12/$O12,"")) | AF12: =IF($A12="","",IFERROR($AD12/$AB12,"")) | AG12: =IF($A12="","",IFERROR(($P12/$O12)/$AD12,"")) | AH12: =IF($A12="","",IFERROR($Q12/$P12,"")) | AI12: =IF($A12="","",IFERROR($AF12*$AG12*$AH12,"")) | AJ12: =IF($A12="","",IFERROR($AE12/$F12,"")) | AK12: =IF($A12="","",IFERROR($AD12/$N12,"")) | AL12: =IF($A12="","",IFERROR($H12/$N12,"")) | AM12: =IF($A12="","",IFERROR(($P12-$Q12)/$P12*1000000,"")) | AN12: =IF($A12="","",IFERROR(($Q12+$R12)/$T12,"")) | AO12: =IF($A12="","",IFERROR($V12/$U12,"")) | AP12: =IF($A12="","",IFERROR(MAX(0,$AD12-$P12/$O12),"")) | AQ12: =IF($A12="","",IFERROR(($P12-$Q12)/$O12,"")) | AR12: =IF($A12="","",IF($F12="","Temps d'ouverture manquant",IF($O12="","Cadence produit inconnue",IF($G12>$F12,"Arrêts planifiés > temps d'ouverture",IF($AC12>$AB12,"Arrêts subis > temps requis",IF($P12<>$Q12+$R12+$S12,"Produite ≠ conforme + retouchée + rebutée",IF($Q12>$P12,"Conforme > produite",IF($V12>$U12,"Présents > prévus","OK")))))))) | AS12: =IF($A12="",0,IF(AND(OR(COCKPIT!$H$4="Toutes",$C12=COCKPIT!$H$4),OR(COCKPIT!$K$4="Toutes",$B12=COCKPIT!$K$4)),1,0))
A13: 46030 | B13: Équipe A (matin) | C13: Ligne 1 - Assemblage | D13: OF-01009 | E13: REF-1001 | F13: 480 | G13: 40 | H13: 24 | I13: 18 | J13: 0 | K13: 0 | L13: 0 | M13: 0 | N13: 1 | O13: =IF($E13="","",IFERROR(INDEX(PARAMETRES!$O$7:$O$36,MATCH($E13,PARAMETRES!$M$7:$M$36,0)),"")) | P13: 5611 | Q13: 5543 | R13: 30 | S13: 38 | T13: 5992 | U13: 12 | V13: 12 | W13: 0 | X13: 0 | Y13: 0 | Z13: PAN-01 | AA13: Panne mécanique — Assemblage | AB13: =IF($A13="","",MAX(0,$F13-$G13)) | AC13: =IF($A13="","",SUM($H13:$M13)) | AD13: =IF($A13="","",MAX(0,$AB13-$AC13)) | AE13: =IF($A13="","",IFERROR($Q13/$O13,"")) | AF13: =IF($A13="","",IFERROR($AD13/$AB13,"")) | AG13: =IF($A13="","",IFERROR(($P13/$O13)/$AD13,"")) | AH13: =IF($A13="","",IFERROR($Q13/$P13,"")) | AI13: =IF($A13="","",IFERROR($AF13*$AG13*$AH13,"")) | AJ13: =IF($A13="","",IFERROR($AE13/$F13,"")) | AK13: =IF($A13="","",IFERROR($AD13/$N13,"")) | AL13: =IF($A13="","",IFERROR($H13/$N13,"")) | AM13: =IF($A13="","",IFERROR(($P13-$Q13)/$P13*1000000,"")) | AN13: =IF($A13="","",IFERROR(($Q13+$R13)/$T13,"")) | AO13: =IF($A13="","",IFERROR($V13/$U13,"")) | AP13: =IF($A13="","",IFERROR(MAX(0,$AD13-$P13/$O13),"")) | AQ13: =IF($A13="","",IFERROR(($P13-$Q13)/$O13,"")) | AR13: =IF($A13="","",IF($F13="","Temps d'ouverture manquant",IF($O13="","Cadence produit inconnue",IF($G13>$F13,"Arrêts planifiés > temps d'ouverture",IF($AC13>$AB13,"Arrêts subis > temps requis",IF($P13<>$Q13+$R13+$S13,"Produite ≠ conforme + retouchée + rebutée",IF($Q13>$P13,"Conforme > produite",IF($V13>$U13,"Présents > prévus","OK")))))))) | AS13: =IF($A13="",0,IF(AND(OR(COCKPIT!$H$4="Toutes",$C13=COCKPIT!$H$4),OR(COCKPIT!$K$4="Toutes",$B13=COCKPIT!$K$4)),1,0))
A14: 46030 | B14: Équipe B (après-midi) | C14: Ligne 2 - Usinage | D14: OF-01010 | E14: REF-2001 | F14: 480 | G14: 40 | H14: 0 | I14: 0 | J14: 7 | K14: 23 | L14: 0 | M14: 14 | N14: 0 | O14: =IF($E14="","",IFERROR(INDEX(PARAMETRES!$O$7:$O$36,MATCH($E14,PARAMETRES!$M$7:$M$36,0)),"")) | P14: 3207 | Q14: 3178 | R14: 13 | S14: 16 | T14: 3394 | U14: 8 | V14: 8 | W14: 0 | X14: 0 | Y14: 1 | Z14: MAT-02 | AA14: Matière non conforme (rebut fournisseur) — Usinage | AB14: =IF($A14="","",MAX(0,$F14-$G14)) | AC14: =IF($A14="","",SUM($H14:$M14)) | AD14: =IF($A14="","",MAX(0,$AB14-$AC14)) | AE14: =IF($A14="","",IFERROR($Q14/$O14,"")) | AF14: =IF($A14="","",IFERROR($AD14/$AB14,"")) | AG14: =IF($A14="","",IFERROR(($P14/$O14)/$AD14,"")) | AH14: =IF($A14="","",IFERROR($Q14/$P14,"")) | AI14: =IF($A14="","",IFERROR($AF14*$AG14*$AH14,"")) | AJ14: =IF($A14="","",IFERROR($AE14/$F14,"")) | AK14: =IF($A14="","",IFERROR($AD14/$N14,"")) | AL14: =IF($A14="","",IFERROR($H14/$N14,"")) | AM14: =IF($A14="","",IFERROR(($P14-$Q14)/$P14*1000000,"")) | AN14: =IF($A14="","",IFERROR(($Q14+$R14)/$T14,"")) | AO14: =IF($A14="","",IFERROR($V14/$U14,"")) | AP14: =IF($A14="","",IFERROR(MAX(0,$AD14-$P14/$O14),"")) | AQ14: =IF($A14="","",IFERROR(($P14-$Q14)/$O14,"")) | AR14: =IF($A14="","",IF($F14="","Temps d'ouverture manquant",IF($O14="","Cadence produit inconnue",IF($G14>$F14,"Arrêts planifiés > temps d'ouverture",IF($AC14>$AB14,"Arrêts subis > temps requis",IF($P14<>$Q14+$R14+$S14,"Produite ≠ conforme + retouchée + rebutée",IF($Q14>$P14,"Conforme > produite",IF($V14>$U14,"Présents > prévus","OK")))))))) | AS14: =IF($A14="",0,IF(AND(OR(COCKPIT!$H$4="Toutes",$C14=COCKPIT!$H$4),OR(COCKPIT!$K$4="Toutes",$B14=COCKPIT!$K$4)),1,0))
A15: 46031 | B15: Équipe B (après-midi) | C15: Ligne 1 - Assemblage | D15: OF-01011 | E15: REF-1002 | F15: 480 | G15: 40 | H15: 37 | I15: 0 | J15: 12 | K15: 19 | L15: 24 | M15: 10 | N15: 1 | O15: =IF($E15="","",IFERROR(INDEX(PARAMETRES!$O$7:$O$36,MATCH($E15,PARAMETRES!$M$7:$M$36,0)),"")) | P15: 4056 | Q15: 4027 | R15: 13 | S15: 16 | T15: 4040 | U15: 12 | V15: 12 | W15: 0 | X15: 0 | Y15: 0 | Z15: PAN-03 | AA15: Défaut automatisme / supervision — Assemblage | AB15: =IF($A15="","",MAX(0,$F15-$G15)) | AC15: =IF($A15="","",SUM($H15:$M15)) | AD15: =IF($A15="","",MAX(0,$AB15-$AC15)) | AE15: =IF($A15="","",IFERROR($Q15/$O15,"")) | AF15: =IF($A15="","",IFERROR($AD15/$AB15,"")) | AG15: =IF($A15="","",IFERROR(($P15/$O15)/$AD15,"")) | AH15: =IF($A15="","",IFERROR($Q15/$P15,"")) | AI15: =IF($A15="","",IFERROR($AF15*$AG15*$AH15,"")) | AJ15: =IF($A15="","",IFERROR($AE15/$F15,"")) | AK15: =IF($A15="","",IFERROR($AD15/$N15,"")) | AL15: =IF($A15="","",IFERROR($H15/$N15,"")) | AM15: =IF($A15="","",IFERROR(($P15-$Q15)/$P15*1000000,"")) | AN15: =IF($A15="","",IFERROR(($Q15+$R15)/$T15,"")) | AO15: =IF($A15="","",IFERROR($V15/$U15,"")) | AP15: =IF($A15="","",IFERROR(MAX(0,$AD15-$P15/$O15),"")) | AQ15: =IF($A15="","",IFERROR(($P15-$Q15)/$O15,"")) | AR15: =IF($A15="","",IF($F15="","Temps d'ouverture manquant",IF($O15="","Cadence produit inconnue",IF($G15>$F15,"Arrêts planifiés > temps d'ouverture",IF($AC15>$AB15,"Arrêts subis > temps requis",IF($P15<>$Q15+$R15+$S15,"Produite ≠ conforme + retouchée + rebutée",IF($Q15>$P15,"Conforme > produite",IF($V15>$U15,"Présents > prévus","OK")))))))) | AS15: =IF($A15="",0,IF(AND(OR(COCKPIT!$H$4="Toutes",$C15=COCKPIT!$H$4),OR(COCKPIT!$K$4="Toutes",$B15=COCKPIT!$K$4)),1,0))
A16: 46031 | B16: Équipe A (matin) | C16: Ligne 2 - Usinage | D16: OF-01012 | E16: REF-2002 | F16: 480 | G16: 40 | H16: 23 | I16: 0 | J16: 0 | K16: 0 | L16: 0 | M16: 20 | N16: 1 | O16: =IF($E16="","",IFERROR(INDEX(PARAMETRES!$O$7:$O$36,MATCH($E16,PARAMETRES!$M$7:$M$36,0)),"")) | P16: 2739 | Q16: 2689 | R16: 22 | S16: 28 | T16: 2946 | U16: 8 | V16: 8 | W16: 4 | X16: 0 | Y16: 0 | Z16: PAN-02 | AA16: Panne électrique ou capteur — Usinage | AB16: =IF($A16="","",MAX(0,$F16-$G16)) | AC16: =IF($A16="","",SUM($H16:$M16)) | AD16: =IF($A16="","",MAX(0,$AB16-$AC16)) | AE16: =IF($A16="","",IFERROR($Q16/$O16,"")) | AF16: =IF($A16="","",IFERROR($AD16/$AB16,"")) | AG16: =IF($A16="","",IFERROR(($P16/$O16)/$AD16,"")) | AH16: =IF($A16="","",IFERROR($Q16/$P16,"")) | AI16: =IF($A16="","",IFERROR($AF16*$AG16*$AH16,"")) | AJ16: =IF($A16="","",IFERROR($AE16/$F16,"")) | AK16: =IF($A16="","",IFERROR($AD16/$N16,"")) | AL16: =IF($A16="","",IFERROR($H16/$N16,"")) | AM16: =IF($A16="","",IFERROR(($P16-$Q16)/$P16*1000000,"")) | AN16: =IF($A16="","",IFERROR(($Q16+$R16)/$T16,"")) | AO16: =IF($A16="","",IFERROR($V16/$U16,"")) | AP16: =IF($A16="","",IFERROR(MAX(0,$AD16-$P16/$O16),"")) | AQ16: =IF($A16="","",IFERROR(($P16-$Q16)/$O16,"")) | AR16: =IF($A16="","",IF($F16="","Temps d'ouverture manquant",IF($O16="","Cadence produit inconnue",IF($G16>$F16,"Arrêts planifiés > temps d'ouverture",IF($AC16>$AB16,"Arrêts subis > temps requis",IF($P16<>$Q16+$R16+$S16,"Produite ≠ conforme + retouchée + rebutée",IF($Q16>$P16,"Conforme > produite",IF($V16>$U16,"Présents > prévus","OK")))))))) | AS16: =IF($A16="",0,IF(AND(OR(COCKPIT!$H$4="Toutes",$C16=COCKPIT!$H$4),OR(COCKPIT!$K$4="Toutes",$B16=COCKPIT!$K$4)),1,0))
... A46: 46052 | B46: Équipe B (après-midi) | C46: Ligne 2 - Usinage | D46: OF-01042 | E46: REF-2001 | F46: 480 | G46: 40 | H46: 0 | I46: 0 | J46: 8 | K46: 20 | L46: 0 | M46: 11 | N46: 0 | O46: =IF($E46="","",IFERROR(INDEX(PARAMETRES!$O$7:$O$36,MATCH($E46,PARAMETRES!$M$7:$M$36,0)),"")) | P46: 3212 | Q46: 3170 | R46: 18 | S46: 24 | T46: 3253 | U46: 8 | V46: 8 | W46: 0 | X46: 0 | Y46: 0 | Z46: MAT-02 | AA46: Matière non conforme (rebut fournisseur) — Usinage | AB46: =IF($A46="","",MAX(0,$F46-$G46)) | AC46: =IF($A46="","",SUM($H46:$M46)) | AD46: =IF($A46="","",MAX(0,$AB46-$AC46)) | AE46: =IF($A46="","",IFERROR($Q46/$O46,"")) | AF46: =IF($A46="","",IFERROR($AD46/$AB46,"")) | AG46: =IF($A46="","",IFERROR(($P46/$O46)/$AD46,"")) | AH46: =IF($A46="","",IFERROR($Q46/$P46,"")) | AI46: =IF($A46="","",IFERROR($AF46*$AG46*$AH46,"")) | AJ46: =IF($A46="","",IFERROR($AE46/$F46,"")) | AK46: =IF($A46="","",IFERROR($AD46/$N46,"")) | AL46: =IF($A46="","",IFERROR($H46/$N46,"")) | AM46: =IF($A46="","",IFERROR(($P46-$Q46)/$P46*1000000,"")) | AN46: =IF($A46="","",IFERROR(($Q46+$R46)/$T46,"")) | AO46: =IF($A46="","",IFERROR($V46/$U46,"")) | AP46: =IF($A46="","",IFERROR(MAX(0,$AD46-$P46/$O46),"")) | AQ46: =IF($A46="","",IFERROR(($P46-$Q46)/$O46,"")) | AR46: =IF($A46="","",IF($F46="","Temps d'ouverture manquant",IF($O46="","Cadence produit inconnue",IF($G46>$F46,"Arrêts planifiés > temps d'ouverture",IF($AC46>$AB46,"Arrêts subis > temps requis",IF($P46<>$Q46+$R46+$S46,"Produite ≠ conforme + retouchée + rebutée",IF($Q46>$P46,"Conforme > produite",IF($V46>$U46,"Présents > prévus","OK")))))))) | AS46: =IF($A46="",0,IF(AND(OR(COCKPIT!$H$4="Toutes",$C46=COCKPIT!$H$4),OR(COCKPIT!$K$4="Toutes",$B46=COCKPIT!$K$4)),1,0))
O47: =IF($E47="","",IFERROR(INDEX(PARAMETRES!$O$7:$O$36,MATCH($E47,PARAMETRES!$M$7:$M$36,0)),"")) | AB47: =IF($A47="","",MAX(0,$F47-$G47)) | AC47: =IF($A47="","",SUM($H47:$M47)) | AD47: =IF($A47="","",MAX(0,$AB47-$AC47)) | AE47: =IF($A47="","",IFERROR($Q47/$O47,"")) | AF47: =IF($A47="","",IFERROR($AD47/$AB47,"")) | AG47: =IF($A47="","",IFERROR(($P47/$O47)/$AD47,"")) | AH47: =IF($A47="","",IFERROR($Q47/$P47,"")) | AI47: =IF($A47="","",IFERROR($AF47*$AG47*$AH47,"")) | AJ47: =IF($A47="","",IFERROR($AE47/$F47,"")) | AK47: =IF($A47="","",IFERROR($AD47/$N47,"")) | AL47: =IF($A47="","",IFERROR($H47/$N47,"")) | AM47: =IF($A47="","",IFERROR(($P47-$Q47)/$P47*1000000,"")) | AN47: =IF($A47="","",IFERROR(($Q47+$R47)/$T47,"")) | AO47: =IF($A47="","",IFERROR($V47/$U47,"")) | AP47: =IF($A47="","",IFERROR(MAX(0,$AD47-$P47/$O47),"")) | AQ47: =IF($A47="","",IFERROR(($P47-$Q47)/$O47,"")) | AR47: =IF($A47="","",IF($F47="","Temps d'ouverture manquant",IF($O47="","Cadence produit inconnue",IF($G47>$F47,"Arrêts planifiés > temps d'ouverture",IF($AC47>$AB47,"Arrêts subis > temps requis",IF($P47<>$Q47+$R47+$S47,"Produite ≠ conforme + retouchée + rebutée",IF($Q47>$P47,"Conforme > produite",IF($V47>$U47,"Présents > prévus","OK")))))))) | AS47: =IF($A47="",0,IF(AND(OR(COCKPIT!$H$4="Toutes",$C47=COCKPIT!$H$4),OR(COCKPIT!$K$4="Toutes",$B47=COCKPIT!$K$4)),1,0))
O48: =IF($E48="","",IFERROR(INDEX(PARAMETRES!$O$7:$O$36,MATCH($E48,PARAMETRES!$M$7:$M$36,0)),"")) | AB48: =IF($A48="","",MAX(0,$F48-$G48)) | AC48: =IF($A48="","",SUM($H48:$M48)) | AD48: =IF($A48="","",MAX(0,$AB48-$AC48)) | AE48: =IF($A48="","",IFERROR($Q48/$O48,"")) | AF48: =IF($A48="","",IFERROR($AD48/$AB48,"")) | AG48: =IF($A48="","",IFERROR(($P48/$O48)/$AD48,"")) | AH48: =IF($A48="","",IFERROR($Q48/$P48,"")) | AI48: =IF($A48="","",IFERROR($AF48*$AG48*$AH48,"")) | AJ48: =IF($A48="","",IFERROR($AE48/$F48,"")) | AK48: =IF($A48="","",IFERROR($AD48/$N48,"")) | AL48: =IF($A48="","",IFERROR($H48/$N48,"")) | AM48: =IF($A48="","",IFERROR(($P48-$Q48)/$P48*1000000,"")) | AN48: =IF($A48="","",IFERROR(($Q48+$R48)/$T48,"")) | AO48: =IF($A48="","",IFERROR($V48/$U48,"")) | AP48: =IF($A48="","",IFERROR(MAX(0,$AD48-$P48/$O48),"")) | AQ48: =IF($A48="","",IFERROR(($P48-$Q48)/$O48,"")) | AR48: =IF($A48="","",IF($F48="","Temps d'ouverture manquant",IF($O48="","Cadence produit inconnue",IF($G48>$F48,"Arrêts planifiés > temps d'ouverture",IF($AC48>$AB48,"Arrêts subis > temps requis",IF($P48<>$Q48+$R48+$S48,"Produite ≠ conforme + retouchée + rebutée",IF($Q48>$P48,"Conforme > produite",IF($V48>$U48,"Présents > prévus","OK")))))))) | AS48: =IF($A48="",0,IF(AND(OR(COCKPIT!$H$4="Toutes",$C48=COCKPIT!$H$4),OR(COCKPIT!$K$4="Toutes",$B48=COCKPIT!$K$4)),1,0))
O49: =IF($E49="","",IFERROR(INDEX(PARAMETRES!$O$7:$O$36,MATCH($E49,PARAMETRES!$M$7:$M$36,0)),"")) | AB49: =IF($A49="","",MAX(0,$F49-$G49)) | AC49: =IF($A49="","",SUM($H49:$M49)) | AD49: =IF($A49="","",MAX(0,$AB49-$AC49)) | AE49: =IF($A49="","",IFERROR($Q49/$O49,"")) | AF49: =IF($A49="","",IFERROR($AD49/$AB49,"")) | AG49: =IF($A49="","",IFERROR(($P49/$O49)/$AD49,"")) | AH49: =IF($A49="","",IFERROR($Q49/$P49,"")) | AI49: =IF($A49="","",IFERROR($AF49*$AG49*$AH49,"")) | AJ49: =IF($A49="","",IFERROR($AE49/$F49,"")) | AK49: =IF($A49="","",IFERROR($AD49/$N49,"")) | AL49: =IF($A49="","",IFERROR($H49/$N49,"")) | AM49: =IF($A49="","",IFERROR(($P49-$Q49)/$P49*1000000,"")) | AN49: =IF($A49="","",IFERROR(($Q49+$R49)/$T49,"")) | AO49: =IF($A49="","",IFERROR($V49/$U49,"")) | AP49: =IF($A49="","",IFERROR(MAX(0,$AD49-$P49/$O49),"")) | AQ49: =IF($A49="","",IFERROR(($P49-$Q49)/$O49,"")) | AR49: =IF($A49="","",IF($F49="","Temps d'ouverture manquant",IF($O49="","Cadence produit inconnue",IF($G49>$F49,"Arrêts planifiés > temps d'ouverture",IF($AC49>$AB49,"Arrêts subis > temps requis",IF($P49<>$Q49+$R49+$S49,"Produite ≠ conforme + retouchée + rebutée",IF($Q49>$P49,"Conforme > produite",IF($V49>$U49,"Présents > prévus","OK")))))))) | AS49: =IF($A49="",0,IF(AND(OR(COCKPIT!$H$4="Toutes",$C49=COCKPIT!$H$4),OR(COCKPIT!$K$4="Toutes",$B49=COCKPIT!$K$4)),1,0))
O50: =IF($E50="","",IFERROR(INDEX(PARAMETRES!$O$7:$O$36,MATCH($E50,PARAMETRES!$M$7:$M$36,0)),"")) | AB50: =IF($A50="","",MAX(0,$F50-$G50)) | AC50: =IF($A50="","",SUM($H50:$M50)) | AD50: =IF($A50="","",MAX(0,$AB50-$AC50)) | AE50: =IF($A50="","",IFERROR($Q50/$O50,"")) | AF50: =IF($A50="","",IFERROR($AD50/$AB50,"")) | AG50: =IF($A50="","",IFERROR(($P50/$O50)/$AD50,"")) | AH50: =IF($A50="","",IFERROR($Q50/$P50,"")) | AI50: =IF($A50="","",IFERROR($AF50*$AG50*$AH50,"")) | AJ50: =IF($A50="","",IFERROR($AE50/$F50,"")) | AK50: =IF($A50="","",IFERROR($AD50/$N50,"")) | AL50: =IF($A50="","",IFERROR($H50/$N50,"")) | AM50: =IF($A50="","",IFERROR(($P50-$Q50)/$P50*1000000,"")) | AN50: =IF($A50="","",IFERROR(($Q50+$R50)/$T50,"")) | AO50: =IF($A50="","",IFERROR($V50/$U50,"")) | AP50: =IF($A50="","",IFERROR(MAX(0,$AD50-$P50/$O50),"")) | AQ50: =IF($A50="","",IFERROR(($P50-$Q50)/$O50,"")) | AR50: =IF($A50="","",IF($F50="","Temps d'ouverture manquant",IF($O50="","Cadence produit inconnue",IF($G50>$F50,"Arrêts planifiés > temps d'ouverture",IF($AC50>$AB50,"Arrêts subis > temps requis",IF($P50<>$Q50+$R50+$S50,"Produite ≠ conforme + retouchée + rebutée",IF($Q50>$P50,"Conforme > produite",IF($V50>$U50,"Présents > prévus","OK")))))))) | AS50: =IF($A50="",0,IF(AND(OR(COCKPIT!$H$4="Toutes",$C50=COCKPIT!$H$4),OR(COCKPIT!$K$4="Toutes",$B50=COCKPIT!$K$4)),1,0))
O51: =IF($E51="","",IFERROR(INDEX(PARAMETRES!$O$7:$O$36,MATCH($E51,PARAMETRES!$M$7:$M$36,0)),"")) | AB51: =IF($A51="","",MAX(0,$F51-$G51)) | AC51: =IF($A51="","",SUM($H51:$M51)) | AD51: =IF($A51="","",MAX(0,$AB51-$AC51)) | AE51: =IF($A51="","",IFERROR($Q51/$O51,"")) | AF51: =IF($A51="","",IFERROR($AD51/$AB51,"")) | AG51: =IF($A51="","",IFERROR(($P51/$O51)/$AD51,"")) | AH51: =IF($A51="","",IFERROR($Q51/$P51,"")) | AI51: =IF($A51="","",IFERROR($AF51*$AG51*$AH51,"")) | AJ51: =IF($A51="","",IFERROR($AE51/$F51,"")) | AK51: =IF($A51="","",IFERROR($AD51/$N51,"")) | AL51: =IF($A51="","",IFERROR($H51/$N51,"")) | AM51: =IF($A51="","",IFERROR(($P51-$Q51)/$P51*1000000,"")) | AN51: =IF($A51="","",IFERROR(($Q51+$R51)/$T51,"")) | AO51: =IF($A51="","",IFERROR($V51/$U51,"")) | AP51: =IF($A51="","",IFERROR(MAX(0,$AD51-$P51/$O51),"")) | AQ51: =IF($A51="","",IFERROR(($P51-$Q51)/$O51,"")) | AR51: =IF($A51="","",IF($F51="","Temps d'ouverture manquant",IF($O51="","Cadence produit inconnue",IF($G51>$F51,"Arrêts planifiés > temps d'ouverture",IF($AC51>$AB51,"Arrêts subis > temps requis",IF($P51<>$Q51+$R51+$S51,"Produite ≠ conforme + retouchée + rebutée",IF($Q51>$P51,"Conforme > produite",IF($V51>$U51,"Présents > prévus","OK")))))))) | AS51: =IF($A51="",0,IF(AND(OR(COCKPIT!$H$4="Toutes",$C51=COCKPIT!$H$4),OR(COCKPIT!$K$4="Toutes",$B51=COCKPIT!$K$4)),1,0))
O52: =IF($E52="","",IFERROR(INDEX(PARAMETRES!$O$7:$O$36,MATCH($E52,PARAMETRES!$M$7:$M$36,0)),"")) | AB52: =IF($A52="","",MAX(0,$F52-$G52)) | AC52: =IF($A52="","",SUM($H52:$M52)) | AD52: =IF($A52="","",MAX(0,$AB52-$AC52)) | AE52: =IF($A52="","",IFERROR($Q52/$O52,"")) | AF52: =IF($A52="","",IFERROR($AD52/$AB52,"")) | AG52: =IF($A52="","",IFERROR(($P52/$O52)/$AD52,"")) | AH52: =IF($A52="","",IFERROR($Q52/$P52,"")) | AI52: =IF($A52="","",IFERROR($AF52*$AG52*$AH52,"")) | AJ52: =IF($A52="","",IFERROR($AE52/$F52,"")) | AK52: =IF($A52="","",IFERROR($AD52/$N52,"")) | AL52: =IF($A52="","",IFERROR($H52/$N52,"")) | AM52: =IF($A52="","",IFERROR(($P52-$Q52)/$P52*1000000,"")) | AN52: =IF($A52="","",IFERROR(($Q52+$R52)/$T52,"")) | AO52: =IF($A52="","",IFERROR($V52/$U52,"")) | AP52: =IF($A52="","",IFERROR(MAX(0,$AD52-$P52/$O52),"")) | AQ52: =IF($A52="","",IFERROR(($P52-$Q52)/$O52,"")) | AR52: =IF($A52="","",IF($F52="","Temps d'ouverture manquant",IF($O52="","Cadence produit inconnue",IF($G52>$F52,"Arrêts planifiés > temps d'ouverture",IF($AC52>$AB52,"Arrêts subis > temps requis",IF($P52<>$Q52+$R52+$S52,"Produite ≠ conforme + retouchée + rebutée",IF($Q52>$P52,"Conforme > produite",IF($V52>$U52,"Présents > prévus","OK")))))))) | AS52: =IF($A52="",0,IF(AND(OR(COCKPIT!$H$4="Toutes",$C52=COCKPIT!$H$4),OR(COCKPIT!$K$4="Toutes",$B52=COCKPIT!$K$4)),1,0))
O53: =IF($E53="","",IFERROR(INDEX(PARAMETRES!$O$7:$O$36,MATCH($E53,PARAMETRES!$M$7:$M$36,0)),"")) | AB53: =IF($A53="","",MAX(0,$F53-$G53)) | AC53: =IF($A53="","",SUM($H53:$M53)) | AD53: =IF($A53="","",MAX(0,$AB53-$AC53)) | AE53: =IF($A53="","",IFERROR($Q53/$O53,"")) | AF53: =IF($A53="","",IFERROR($AD53/$AB53,"")) | AG53: =IF($A53="","",IFERROR(($P53/$O53)/$AD53,"")) | AH53: =IF($A53="","",IFERROR($Q53/$P53,"")) | AI53: =IF($A53="","",IFERROR($AF53*$AG53*$AH53,"")) | AJ53: =IF($A53="","",IFERROR($AE53/$F53,"")) | AK53: =IF($A53="","",IFERROR($AD53/$N53,"")) | AL53: =IF($A53="","",IFERROR($H53/$N53,"")) | AM53: =IF($A53="","",IFERROR(($P53-$Q53)/$P53*1000000,"")) | AN53: =IF($A53="","",IFERROR(($Q53+$R53)/$T53,"")) | AO53: =IF($A53="","",IFERROR($V53/$U53,"")) | AP53: =IF($A53="","",IFERROR(MAX(0,$AD53-$P53/$O53),"")) | AQ53: =IF($A53="","",IFERROR(($P53-$Q53)/$O53,"")) | AR53: =IF($A53="","",IF($F53="","Temps d'ouverture manquant",IF($O53="","Cadence produit inconnue",IF($G53>$F53,"Arrêts planifiés > temps d'ouverture",IF($AC53>$AB53,"Arrêts subis > temps requis",IF($P53<>$Q53+$R53+$S53,"Produite ≠ conforme + retouchée + rebutée",IF($Q53>$P53,"Conforme > produite",IF($V53>$U53,"Présents > prévus","OK")))))))) | AS53: =IF($A53="",0,IF(AND(OR(COCKPIT!$H$4="Toutes",$C53=COCKPIT!$H$4),OR(COCKPIT!$K$4="Toutes",$B53=COCKPIT!$K$4)),1,0))
O54: =IF($E54="","",IFERROR(INDEX(PARAMETRES!$O$7:$O$36,MATCH($E54,PARAMETRES!$M$7:$M$36,0)),"")) | AB54: =IF($A54="","",MAX(0,$F54-$G54)) | AC54: =IF($A54="","",SUM($H54:$M54)) | AD54: =IF($A54="","",MAX(0,$AB54-$AC54)) | AE54: =IF($A54="","",IFERROR($Q54/$O54,"")) | AF54: =IF($A54="","",IFERROR($AD54/$AB54,"")) | AG54: =IF($A54="","",IFERROR(($P54/$O54)/$AD54,"")) | AH54: =IF($A54="","",IFERROR($Q54/$P54,"")) | AI54: =IF($A54="","",IFERROR($AF54*$AG54*$AH54,"")) | AJ54: =IF($A54="","",IFERROR($AE54/$F54,"")) | AK54: =IF($A54="","",IFERROR($AD54/$N54,"")) | AL54: =IF($A54="","",IFERROR($H54/$N54,"")) | AM54: =IF($A54="","",IFERROR(($P54-$Q54)/$P54*1000000,"")) | AN54: =IF($A54="","",IFERROR(($Q54+$R54)/$T54,"")) | AO54: =IF($A54="","",IFERROR($V54/$U54,"")) | AP54: =IF($A54="","",IFERROR(MAX(0,$AD54-$P54/$O54),"")) | AQ54: =IF($A54="","",IFERROR(($P54-$Q54)/$O54,"")) | AR54: =IF($A54="","",IF($F54="","Temps d'ouverture manquant",IF($O54="","Cadence produit inconnue",IF($G54>$F54,"Arrêts planifiés > temps d'ouverture",IF($AC54>$AB54,"Arrêts subis > temps requis",IF($P54<>$Q54+$R54+$S54,"Produite ≠ conforme + retouchée + rebutée",IF($Q54>$P54,"Conforme > produite",IF($V54>$U54,"Présents > prévus","OK")))))))) | AS54: =IF($A54="",0,IF(AND(OR(COCKPIT!$H$4="Toutes",$C54=COCKPIT!$H$4),OR(COCKPIT!$K$4="Toutes",$B54=COCKPIT!$K$4)),1,0))
O55: =IF($E55="","",IFERROR(INDEX(PARAMETRES!$O$7:$O$36,MATCH($E55,PARAMETRES!$M$7:$M$36,0)),"")) | AB55: =IF($A55="","",MAX(0,$F55-$G55)) | AC55: =IF($A55="","",SUM($H55:$M55)) | AD55: =IF($A55="","",MAX(0,$AB55-$AC55)) | AE55: =IF($A55="","",IFERROR($Q55/$O55,"")) | AF55: =IF($A55="","",IFERROR($AD55/$AB55,"")) | AG55: =IF($A55="","",IFERROR(($P55/$O55)/$AD55,"")) | AH55: =IF($A55="","",IFERROR($Q55/$P55,"")) | AI55: =IF($A55="","",IFERROR($AF55*$AG55*$AH55,"")) | AJ55: =IF($A55="","",IFERROR($AE55/$F55,"")) | AK55: =IF($A55="","",IFERROR($AD55/$N55,"")) | AL55: =IF($A55="","",IFERROR($H55/$N55,"")) | AM55: =IF($A55="","",IFERROR(($P55-$Q55)/$P55*1000000,"")) | AN55: =IF($A55="","",IFERROR(($Q55+$R55)/$T55,"")) | AO55: =IF($A55="","",IFERROR($V55/$U55,"")) | AP55: =IF($A55="","",IFERROR(MAX(0,$AD55-$P55/$O55),"")) | AQ55: =IF($A55="","",IFERROR(($P55-$Q55)/$O55,"")) | AR55: =IF($A55="","",IF($F55="","Temps d'ouverture manquant",IF($O55="","Cadence produit inconnue",IF($G55>$F55,"Arrêts planifiés > temps d'ouverture",IF($AC55>$AB55,"Arrêts subis > temps requis",IF($P55<>$Q55+$R55+$S55,"Produite ≠ conforme + retouchée + rebutée",IF($Q55>$P55,"Conforme > produite",IF($V55>$U55,"Présents > prévus","OK")))))))) | AS55: =IF($A55="",0,IF(AND(OR(COCKPIT!$H$4="Toutes",$C55=COCKPIT!$H$4),OR(COCKPIT!$K$4="Toutes",$B55=COCKPIT!$K$4)),1,0))
O56: =IF($E56="","",IFERROR(INDEX(PARAMETRES!$O$7:$O$36,MATCH($E56,PARAMETRES!$M$7:$M$36,0)),"")) | AB56: =IF($A56="","",MAX(0,$F56-$G56)) | AC56: =IF($A56="","",SUM($H56:$M56)) | AD56: =IF($A56="","",MAX(0,$AB56-$AC56)) | AE56: =IF($A56="","",IFERROR($Q56/$O56,"")) | AF56: =IF($A56="","",IFERROR($AD56/$AB56,"")) | AG56: =IF($A56="","",IFERROR(($P56/$O56)/$AD56,"")) | AH56: =IF($A56="","",IFERROR($Q56/$P56,"")) | AI56: =IF($A56="","",IFERROR($AF56*$AG56*$AH56,"")) | AJ56: =IF($A56="","",IFERROR($AE56/$F56,"")) | AK56: =IF($A56="","",IFERROR($AD56/$N56,"")) | AL56: =IF($A56="","",IFERROR($H56/$N56,"")) | AM56: =IF($A56="","",IFERROR(($P56-$Q56)/$P56*1000000,"")) | AN56: =IF($A56="","",IFERROR(($Q56+$R56)/$T56,"")) | AO56: =IF($A56="","",IFERROR($V56/$U56,"")) | AP56: =IF($A56="","",IFERROR(MAX(0,$AD56-$P56/$O56),"")) | AQ56: =IF($A56="","",IFERROR(($P56-$Q56)/$O56,"")) | AR56: =IF($A56="","",IF($F56="","Temps d'ouverture manquant",IF($O56="","Cadence produit inconnue",IF($G56>$F56,"Arrêts planifiés > temps d'ouverture",IF($AC56>$AB56,"Arrêts subis > temps requis",IF($P56<>$Q56+$R56+$S56,"Produite ≠ conforme + retouchée + rebutée",IF($Q56>$P56,"Conforme > produite",IF($V56>$U56,"Présents > prévus","OK")))))))) | AS56: =IF($A56="",0,IF(AND(OR(COCKPIT!$H$4="Toutes",$C56=COCKPIT!$H$4),OR(COCKPIT!$K$4="Toutes",$B56=COCKPIT!$K$4)),1,0))
O57: =IF($E57="","",IFERROR(INDEX(PARAMETRES!$O$7:$O$36,MATCH($E57,PARAMETRES!$M$7:$M$36,0)),"")) | AB57: =IF($A57="","",MAX(0,$F57-$G57)) | AC57: =IF($A57="","",SUM($H57:$M57)) | AD57: =IF($A57="","",MAX(0,$AB57-$AC57)) | AE57: =IF($A57="","",IFERROR($Q57/$O57,"")) | AF57: =IF($A57="","",IFERROR($AD57/$AB57,"")) | AG57: =IF($A57="","",IFERROR(($P57/$O57)/$AD57,"")) | AH57: =IF($A57="","",IFERROR($Q57/$P57,"")) | AI57: =IF($A57="","",IFERROR($AF57*$AG57*$AH57,"")) | AJ57: =IF($A57="","",IFERROR($AE57/$F57,"")) | AK57: =IF($A57="","",IFERROR($AD57/$N57,"")) | AL57: =IF($A57="","",IFERROR($H57/$N57,"")) | AM57: =IF($A57="","",IFERROR(($P57-$Q57)/$P57*1000000,"")) | AN57: =IF($A57="","",IFERROR(($Q57+$R57)/$T57,"")) | AO57: =IF($A57="","",IFERROR($V57/$U57,"")) | AP57: =IF($A57="","",IFERROR(MAX(0,$AD57-$P57/$O57),"")) | AQ57: =IF($A57="","",IFERROR(($P57-$Q57)/$O57,"")) | AR57: =IF($A57="","",IF($F57="","Temps d'ouverture manquant",IF($O57="","Cadence produit inconnue",IF($G57>$F57,"Arrêts planifiés > temps d'ouverture",IF($AC57>$AB57,"Arrêts subis > temps requis",IF($P57<>$Q57+$R57+$S57,"Produite ≠ conforme + retouchée + rebutée",IF($Q57>$P57,"Conforme > produite",IF($V57>$U57,"Présents > prévus","OK")))))))) | AS57: =IF($A57="",0,IF(AND(OR(COCKPIT!$H$4="Toutes",$C57=COCKPIT!$H$4),OR(COCKPIT!$K$4="Toutes",$B57=COCKPIT!$K$4)),1,0))
O58: =IF($E58="","",IFERROR(INDEX(PARAMETRES!$O$7:$O$36,MATCH($E58,PARAMETRES!$M$7:$M$36,0)),"")) | AB58: =IF($A58="","",MAX(0,$F58-$G58)) | AC58: =IF($A58="","",SUM($H58:$M58)) | AD58: =IF($A58="","",MAX(0,$AB58-$AC58)) | AE58: =IF($A58="","",IFERROR($Q58/$O58,"")) | AF58: =IF($A58="","",IFERROR($AD58/$AB58,"")) | AG58: =IF($A58="","",IFERROR(($P58/$O58)/$AD58,"")) | AH58: =IF($A58="","",IFERROR($Q58/$P58,"")) | AI58: =IF($A58="","",IFERROR($AF58*$AG58*$AH58,"")) | AJ58: =IF($A58="","",IFERROR($AE58/$F58,"")) | AK58: =IF($A58="","",IFERROR($AD58/$N58,"")) | AL58: =IF($A58="","",IFERROR($H58/$N58,"")) | AM58: =IF($A58="","",IFERROR(($P58-$Q58)/$P58*1000000,"")) | AN58: =IF($A58="","",IFERROR(($Q58+$R58)/$T58,"")) | AO58: =IF($A58="","",IFERROR($V58/$U58,"")) | AP58: =IF($A58="","",IFERROR(MAX(0,$AD58-$P58/$O58),"")) | AQ58: =IF($A58="","",IFERROR(($P58-$Q58)/$O58,"")) | AR58: =IF($A58="","",IF($F58="","Temps d'ouverture manquant",IF($O58="","Cadence produit inconnue",IF($G58>$F58,"Arrêts planifiés > temps d'ouverture",IF($AC58>$AB58,"Arrêts subis > temps requis",IF($P58<>$Q58+$R58+$S58,"Produite ≠ conforme + retouchée + rebutée",IF($Q58>$P58,"Conforme > produite",IF($V58>$U58,"Présents > prévus","OK")))))))) | AS58: =IF($A58="",0,IF(AND(OR(COCKPIT!$H$4="Toutes",$C58=COCKPIT!$H$4),OR(COCKPIT!$K$4="Toutes",$B58=COCKPIT!$K$4)),1,0))
... O204: =IF($E204="","",IFERROR(INDEX(PARAMETRES!$O$7:$O$36,MATCH($E204,PARAMETRES!$M$7:$M$36,0)),"")) | AB204: =IF($A204="","",MAX(0,$F204-$G204)) | AC204: =IF($A204="","",SUM($H204:$M204)) | AD204: =IF($A204="","",MAX(0,$AB204-$AC204)) | AE204: =IF($A204="","",IFERROR($Q204/$O204,"")) | AF204: =IF($A204="","",IFERROR($AD204/$AB204,"")) | AG204: =IF($A204="","",IFERROR(($P204/$O204)/$AD204,"")) | AH204: =IF($A204="","",IFERROR($Q204/$P204,"")) | AI204: =IF($A204="","",IFERROR($AF204*$AG204*$AH204,"")) | AJ204: =IF($A204="","",IFERROR($AE204/$F204,"")) | AK204: =IF($A204="","",IFERROR($AD204/$N204,"")) | AL204: =IF($A204="","",IFERROR($H204/$N204,"")) | AM204: =IF($A204="","",IFERROR(($P204-$Q204)/$P204*1000000,"")) | AN204: =IF($A204="","",IFERROR(($Q204+$R204)/$T204,"")) | AO204: =IF($A204="","",IFERROR($V204/$U204,"")) | AP204: =IF($A204="","",IFERROR(MAX(0,$AD204-$P204/$O204),"")) | AQ204: =IF($A204="","",IFERROR(($P204-$Q204)/$O204,"")) | AR204: =IF($A204="","",IF($F204="","Temps d'ouverture manquant",IF($O204="","Cadence produit inconnue",IF($G204>$F204,"Arrêts planifiés > temps d'ouverture",IF($AC204>$AB204,"Arrêts subis > temps requis",IF($P204<>$Q204+$R204+$S204,"Produite ≠ conforme + retouchée + rebutée",IF($Q204>$P204,"Conforme > produite",IF($V204>$U204,"Présents > prévus","OK")))))))) | AS204: =IF($A204="",0,IF(AND(OR(COCKPIT!$H$4="Toutes",$C204=COCKPIT!$H$4),OR(COCKPIT!$K$4="Toutes",$B204=COCKPIT!$K$4)),1,0))

Sheet ARRETS
A1: JOURNAL DES ARRÊTS — niveau événementiel
A2: Un enregistrement par arrêt. Ce niveau de détail alimente l'analyse de Pareto par cause et par famille 5M. Les colonnes bleues sont renseignées automatiquement à partir du code cause.
A4: Date | B4: Équipe | C4: Ligne / ressource | D4: Machine / poste | E4: Heure de début | F4: Heure de fin | G4: Durée (min) | H4: Code cause | I4: Libellé de la cause | J4: Famille 5M | K4: Type | L4: Rubrique de perte | M4: Constat terrain | N4: Action immédiate appliquée | O4: N° d'action liée | P4: Niveau d'alerte | Q4: Filtre cockpit
A5: 46024 | B5: Équipe A (matin) | C5: Ligne 1 - Assemblage | D5: Ligne 1 | E5: 0.29097222 | F5: 0.31875 | G5: =IF(OR($E5="",$F5=""),"",ROUND(($F5-$E5+IF($F5<$E5,1,0))*1440,0)) | H5: PLA-01 | I5: =IF($H5="","",IFERROR(INDEX(PARAMETRES!$S$7:$S$46,MATCH($H5,PARAMETRES!$R$7:$R$46,0)),"Code inconnu")) | J5: =IF($H5="","",IFERROR(INDEX(PARAMETRES!$T$7:$T$46,MATCH($H5,PARAMETRES!$R$7:$R$46,0)),"")) | K5: =IF($H5="","",IFERROR(INDEX(PARAMETRES!$U$7:$U$46,MATCH($H5,PARAMETRES!$R$7:$R$46,0)),"")) | L5: =IF($H5="","",IFERROR(INDEX(PARAMETRES!$V$7:$V$46,MATCH($H5,PARAMETRES!$R$7:$R$46,0)),"")) | P5: =IF($G5="","",IF($G5>=60,"Arrêt majeur — analyse 5 pourquoi",IF($G5>=30,"À analyser en revue quotidienne",IF($K5="Planifié","Arrêt planifié","Aléa courant")))) | Q5: =IF($A5="",0,IF(AND(OR(COCKPIT!$H$4="Toutes",$C5=COCKPIT!$H$4),OR(COCKPIT!$K$4="Toutes",$B5=COCKPIT!$K$4)),1,0))
A6: 46024 | B6: Équipe A (matin) | C6: Ligne 1 - Assemblage | D6: Ligne 1 | E6: 0.33402778 | F6: 0.36805556 | G6: =IF(OR($E6="",$F6=""),"",ROUND(($F6-$E6+IF($F6<$E6,1,0))*1440,0)) | H6: PAN-01 | I6: =IF($H6="","",IFERROR(INDEX(PARAMETRES!$S$7:$S$46,MATCH($H6,PARAMETRES!$R$7:$R$46,0)),"Code inconnu")) | J6: =IF($H6="","",IFERROR(INDEX(PARAMETRES!$T$7:$T$46,MATCH($H6,PARAMETRES!$R$7:$R$46,0)),"")) | K6: =IF($H6="","",IFERROR(INDEX(PARAMETRES!$U$7:$U$46,MATCH($H6,PARAMETRES!$R$7:$R$46,0)),"")) | L6: =IF($H6="","",IFERROR(INDEX(PARAMETRES!$V$7:$V$46,MATCH($H6,PARAMETRES!$R$7:$R$46,0)),"")) | P6: =IF($G6="","",IF($G6>=60,"Arrêt majeur — analyse 5 pourquoi",IF($G6>=30,"À analyser en revue quotidienne",IF($K6="Planifié","Arrêt planifié","Aléa courant")))) | Q6: =IF($A6="",0,IF(AND(OR(COCKPIT!$H$4="Toutes",$C6=COCKPIT!$H$4),OR(COCKPIT!$K$4="Toutes",$B6=COCKPIT!$K$4)),1,0))
